2024-12-21 14:48:18,310 - __main__ - INFO - База данных инициализирована.
2024-12-21 15:06:56,331 - __main__ - INFO - База данных инициализирована.
2024-12-21 15:06:59,384 - __main__ - INFO - Обработчики добавлены. Бот запускается.
2024-12-21 15:07:01,446 - apscheduler.scheduler - INFO - Scheduler started
2024-12-21 15:07:01,489 - telegram.ext.Application - INFO - Application started
2024-12-21 15:07:05,241 - __main__ - INFO - Пользователь 1753361154 инициировал /start.
2024-12-21 15:07:20,623 - __main__ - INFO - Пользователь 1753361154 зарегистрирован как @shineSwa.
2024-12-21 15:07:36,748 - __main__ - INFO - Пользователь 1753361154 изменил видимость профиля на 0.
2024-12-21 15:07:52,850 - __main__ - INFO - Команда /info вызвана пользователем @shineSwa (1753361154).
2024-12-21 15:08:28,777 - __main__ - INFO - Пользователь 1753361154 изменил видимость профиля на 1.
2024-12-21 15:08:32,205 - __main__ - INFO - Команда /list вызвана.
2024-12-21 15:08:42,305 - __main__ - INFO - Команда /help вызвана.
2024-12-21 15:08:56,425 - __main__ - INFO - Команда /list вызвана.
2024-12-21 15:13:07,726 - __main__ - INFO - Команда /list вызвана.
2024-12-21 15:16:38,689 - __main__ - INFO - Команда /info вызвана пользователем @shineSwa (1753361154).
2024-12-21 15:17:17,104 - __main__ - INFO - Пользователь 1753361154 установил фотографию профиля.
2024-12-21 15:17:20,509 - __main__ - INFO - Команда /info вызвана пользователем @shineSwa (1753361154).
2024-12-21 15:22:33,924 - __main__ - INFO - Пользователь 2128746010 инициировал /start.
2024-12-21 15:22:38,699 - __main__ - INFO - Пользователь 2128746010 зарегистрирован как @Huapryanik.
2024-12-21 15:23:06,885 - __main__ - INFO - Команда /list вызвана.
2024-12-21 15:23:07,947 - __main__ - INFO - Пользователь 2128746010 установил фотографию профиля.
2024-12-21 15:23:13,881 - __main__ - INFO - Команда /help вызвана.
2024-12-21 15:23:18,830 - __main__ - INFO - Команда /info вызвана пользователем @Huapryanik (2128746010).
2024-12-21 15:24:49,408 - __main__ - INFO - Пользователь 1753361154 отправил сообщение пользователю @Huapryanik (2128746010) анонимно=False.
2024-12-21 15:25:39,849 - __main__ - INFO - Команда /list вызвана.
2024-12-21 15:26:13,894 - __main__ - INFO - Пользователь 1753361154 отправил сообщение пользователю @Huapryanik (2128746010) анонимно=False.
2024-12-21 15:26:27,894 - __main__ - INFO - Команда /help вызвана.
2024-12-21 15:26:39,044 - __main__ - INFO - Пользователь 1753361154 поставил лайк пользователю 2128746010 (@Huapryanik).
2024-12-21 15:28:09,843 - __main__ - INFO - Жалоба от 1753361154 на 2128746010: немножко хуй в говне
2024-12-21 15:28:10,363 - __main__ - INFO - Жалоба от 1753361154 на 2128746010 отправлена администратору.
2024-12-21 15:30:07,393 - __main__ - INFO - Команда /list вызвана.
2024-12-21 15:30:24,640 - __main__ - INFO - Пользователь 1753361154 изменил видимость профиля на 0.
2024-12-21 15:30:26,468 - __main__ - INFO - Команда /list вызвана.
2024-12-21 15:30:35,767 - __main__ - INFO - Команда /info вызвана пользователем @Huapryanik (2128746010).
2024-12-21 15:30:43,468 - __main__ - INFO - Команда /list вызвана.
2024-12-21 15:31:00,979 - __main__ - INFO - Команда /list вызвана.
2024-12-21 15:31:05,468 - __main__ - INFO - Пользователь 2128746010 изменил видимость профиля на 0.
2024-12-21 15:31:54,231 - __main__ - INFO - Пользователь 1753361154 изменил видимость профиля на 1.
2024-12-21 15:31:56,020 - __main__ - INFO - Команда /list вызвана.
2024-12-21 15:33:17,110 - __main__ - INFO - Команда /list вызвана.
2024-12-21 15:33:28,295 - __main__ - INFO - Пользователь 2128746010 изменил видимость профиля на 1.
2024-12-21 15:33:33,324 - __main__ - INFO - Команда /list вызвана.
2024-12-21 15:42:15,511 - telegram.ext.Updater - ERROR - Invalid token; aborting
Traceback (most recent call last):
  File "C:\Users\Admin\AppData\Local\Programs\Python\Python312\Lib\site-packages\telegram\ext\_updater.py", line 750, in _network_loop_retry
    if not await do_action():
           ^^^^^^^^^^^^^^^^^
  File "C:\Users\Admin\AppData\Local\Programs\Python\Python312\Lib\site-packages\telegram\ext\_updater.py", line 744, in do_action
    return action_cb_task.result()
           ^^^^^^^^^^^^^^^^^^^^^^^
  File "C:\Users\Admin\AppData\Local\Programs\Python\Python312\Lib\asyncio\futures.py", line 203, in result
    raise self._exception.with_traceback(self._exception_tb)
  File "C:\Users\Admin\AppData\Local\Programs\Python\Python312\Lib\asyncio\tasks.py", line 314, in __step_run_and_handle_result
    result = coro.send(None)
             ^^^^^^^^^^^^^^^
  File "C:\Users\Admin\AppData\Local\Programs\Python\Python312\Lib\site-packages\telegram\ext\_updater.py", line 371, in polling_action_cb
    updates = await self.bot.get_updates(
              ^^^^^^^^^^^^^^^^^^^^^^^^^^^
  File "C:\Users\Admin\AppData\Local\Programs\Python\Python312\Lib\site-packages\telegram\ext\_extbot.py", line 650, in get_updates
    updates = await super().get_updates(
              ^^^^^^^^^^^^^^^^^^^^^^^^^^
  File "C:\Users\Admin\AppData\Local\Programs\Python\Python312\Lib\site-packages\telegram\_bot.py", line 4480, in get_updates
    await self._post(
  File "C:\Users\Admin\AppData\Local\Programs\Python\Python312\Lib\site-packages\telegram\_bot.py", line 619, in _post
    return await self._do_post(
           ^^^^^^^^^^^^^^^^^^^^
  File "C:\Users\Admin\AppData\Local\Programs\Python\Python312\Lib\site-packages\telegram\ext\_extbot.py", line 354, in _do_post
    return await super()._do_post(
           ^^^^^^^^^^^^^^^^^^^^^^^
  File "C:\Users\Admin\AppData\Local\Programs\Python\Python312\Lib\site-packages\telegram\_bot.py", line 648, in _do_post
    result = await request.post(
             ^^^^^^^^^^^^^^^^^^^
  File "C:\Users\Admin\AppData\Local\Programs\Python\Python312\Lib\site-packages\telegram\request\_baserequest.py", line 202, in post
    result = await self._request_wrapper(
             ^^^^^^^^^^^^^^^^^^^^^^^^^^^^
  File "C:\Users\Admin\AppData\Local\Programs\Python\Python312\Lib\site-packages\telegram\request\_baserequest.py", line 381, in _request_wrapper
    raise InvalidToken(message)
telegram.error.InvalidToken: Unauthorized
2024-12-21 15:43:51,183 - __main__ - INFO - База данных инициализирована.
2024-12-21 15:43:54,411 - __main__ - INFO - Обработчики добавлены. Бот запускается.
2024-12-21 15:43:59,585 - apscheduler.scheduler - INFO - Scheduler started
2024-12-21 15:43:59,641 - telegram.ext.Application - INFO - Application started
2024-12-21 15:44:06,163 - __main__ - INFO - Команда /list вызвана.
2024-12-21 15:46:42,762 - __main__ - ERROR - Ошибка при отправке фото профиля пользователю 1753361154: Timed out
2024-12-21 15:46:47,905 - __main__ - ERROR - Обнаружена ошибка:
Traceback (most recent call last):
  File "C:\Users\Admin\AppData\Local\Programs\Python\Python312\Lib\site-packages\httpx\_transports\default.py", line 72, in map_httpcore_exceptions
    yield
  File "C:\Users\Admin\AppData\Local\Programs\Python\Python312\Lib\site-packages\httpx\_transports\default.py", line 377, in handle_async_request
    resp = await self._pool.handle_async_request(req)
           ^^^^^^^^^^^^^^^^^^^^^^^^^^^^^^^^^^^^^^^^^^
  File "C:\Users\Admin\AppData\Local\Programs\Python\Python312\Lib\site-packages\httpcore\_async\connection_pool.py", line 216, in handle_async_request
    raise exc from None
  File "C:\Users\Admin\AppData\Local\Programs\Python\Python312\Lib\site-packages\httpcore\_async\connection_pool.py", line 196, in handle_async_request
    response = await connection.handle_async_request(
               ^^^^^^^^^^^^^^^^^^^^^^^^^^^^^^^^^^^^^^
  File "C:\Users\Admin\AppData\Local\Programs\Python\Python312\Lib\site-packages\httpcore\_async\connection.py", line 99, in handle_async_request
    raise exc
  File "C:\Users\Admin\AppData\Local\Programs\Python\Python312\Lib\site-packages\httpcore\_async\connection.py", line 76, in handle_async_request
    stream = await self._connect(request)
             ^^^^^^^^^^^^^^^^^^^^^^^^^^^^
  File "C:\Users\Admin\AppData\Local\Programs\Python\Python312\Lib\site-packages\httpcore\_async\connection.py", line 122, in _connect
    stream = await self._network_backend.connect_tcp(**kwargs)
             ^^^^^^^^^^^^^^^^^^^^^^^^^^^^^^^^^^^^^^^^^^^^^^^^^
  File "C:\Users\Admin\AppData\Local\Programs\Python\Python312\Lib\site-packages\httpcore\_backends\auto.py", line 30, in connect_tcp
    return await self._backend.connect_tcp(
           ^^^^^^^^^^^^^^^^^^^^^^^^^^^^^^^^
  File "C:\Users\Admin\AppData\Local\Programs\Python\Python312\Lib\site-packages\httpcore\_backends\anyio.py", line 115, in connect_tcp
    with map_exceptions(exc_map):
  File "C:\Users\Admin\AppData\Local\Programs\Python\Python312\Lib\contextlib.py", line 158, in __exit__
    self.gen.throw(value)
  File "C:\Users\Admin\AppData\Local\Programs\Python\Python312\Lib\site-packages\httpcore\_exceptions.py", line 14, in map_exceptions
    raise to_exc(exc) from exc
httpcore.ConnectTimeout

The above exception was the direct cause of the following exception:

Traceback (most recent call last):
  File "C:\Users\Admin\AppData\Local\Programs\Python\Python312\Lib\site-packages\telegram\request\_httpxrequest.py", line 293, in do_request
    res = await self._client.request(
          ^^^^^^^^^^^^^^^^^^^^^^^^^^^
  File "C:\Users\Admin\AppData\Local\Programs\Python\Python312\Lib\site-packages\httpx\_client.py", line 1585, in request
    return await self.send(request, auth=auth, follow_redirects=follow_redirects)
           ^^^^^^^^^^^^^^^^^^^^^^^^^^^^^^^^^^^^^^^^^^^^^^^^^^^^^^^^^^^^^^^^^^^^^^
  File "C:\Users\Admin\AppData\Local\Programs\Python\Python312\Lib\site-packages\httpx\_client.py", line 1674, in send
    response = await self._send_handling_auth(
               ^^^^^^^^^^^^^^^^^^^^^^^^^^^^^^^
  File "C:\Users\Admin\AppData\Local\Programs\Python\Python312\Lib\site-packages\httpx\_client.py", line 1702, in _send_handling_auth
    response = await self._send_handling_redirects(
               ^^^^^^^^^^^^^^^^^^^^^^^^^^^^^^^^^^^^
  File "C:\Users\Admin\AppData\Local\Programs\Python\Python312\Lib\site-packages\httpx\_client.py", line 1739, in _send_handling_redirects
    response = await self._send_single_request(request)
               ^^^^^^^^^^^^^^^^^^^^^^^^^^^^^^^^^^^^^^^^
  File "C:\Users\Admin\AppData\Local\Programs\Python\Python312\Lib\site-packages\httpx\_client.py", line 1776, in _send_single_request
    response = await transport.handle_async_request(request)
               ^^^^^^^^^^^^^^^^^^^^^^^^^^^^^^^^^^^^^^^^^^^^^
  File "C:\Users\Admin\AppData\Local\Programs\Python\Python312\Lib\site-packages\httpx\_transports\default.py", line 376, in handle_async_request
    with map_httpcore_exceptions():
  File "C:\Users\Admin\AppData\Local\Programs\Python\Python312\Lib\contextlib.py", line 158, in __exit__
    self.gen.throw(value)
  File "C:\Users\Admin\AppData\Local\Programs\Python\Python312\Lib\site-packages\httpx\_transports\default.py", line 89, in map_httpcore_exceptions
    raise mapped_exc(message) from exc
httpx.ConnectTimeout

The above exception was the direct cause of the following exception:

Traceback (most recent call last):
  File "C:\Users\Admin\AppData\Local\Programs\Python\Python312\Lib\site-packages\telegram\ext\_application.py", line 1325, in process_update
    await coroutine
  File "C:\Users\Admin\AppData\Local\Programs\Python\Python312\Lib\site-packages\telegram\ext\_handlers\basehandler.py", line 158, in handle_update
    return await self.callback(update, context)
           ^^^^^^^^^^^^^^^^^^^^^^^^^^^^^^^^^^^^
  File "C:\Users\Admin\Desktop\ZN.py", line 1216, in info_command
    await update.message.reply_text(profile_message, parse_mode=ParseMode.HTML)
  File "C:\Users\Admin\AppData\Local\Programs\Python\Python312\Lib\site-packages\telegram\_message.py", line 1771, in reply_text
    return await self.get_bot().send_message(
           ^^^^^^^^^^^^^^^^^^^^^^^^^^^^^^^^^^
  File "C:\Users\Admin\AppData\Local\Programs\Python\Python312\Lib\site-packages\telegram\ext\_extbot.py", line 2965, in send_message
    return await super().send_message(
           ^^^^^^^^^^^^^^^^^^^^^^^^^^^
  File "C:\Users\Admin\AppData\Local\Programs\Python\Python312\Lib\site-packages\telegram\_bot.py", line 1019, in send_message
    return await self._send_message(
           ^^^^^^^^^^^^^^^^^^^^^^^^^
  File "C:\Users\Admin\AppData\Local\Programs\Python\Python312\Lib\site-packages\telegram\ext\_extbot.py", line 610, in _send_message
    result = await super()._send_message(
             ^^^^^^^^^^^^^^^^^^^^^^^^^^^^
  File "C:\Users\Admin\AppData\Local\Programs\Python\Python312\Lib\site-packages\telegram\_bot.py", line 731, in _send_message
    result = await self._post(
             ^^^^^^^^^^^^^^^^^
  File "C:\Users\Admin\AppData\Local\Programs\Python\Python312\Lib\site-packages\telegram\_bot.py", line 619, in _post
    return await self._do_post(
           ^^^^^^^^^^^^^^^^^^^^
  File "C:\Users\Admin\AppData\Local\Programs\Python\Python312\Lib\site-packages\telegram\ext\_extbot.py", line 354, in _do_post
    return await super()._do_post(
           ^^^^^^^^^^^^^^^^^^^^^^^
  File "C:\Users\Admin\AppData\Local\Programs\Python\Python312\Lib\site-packages\telegram\_bot.py", line 648, in _do_post
    result = await request.post(
             ^^^^^^^^^^^^^^^^^^^
  File "C:\Users\Admin\AppData\Local\Programs\Python\Python312\Lib\site-packages\telegram\request\_baserequest.py", line 202, in post
    result = await self._request_wrapper(
             ^^^^^^^^^^^^^^^^^^^^^^^^^^^^
  File "C:\Users\Admin\AppData\Local\Programs\Python\Python312\Lib\site-packages\telegram\request\_baserequest.py", line 334, in _request_wrapper
    code, payload = await self.do_request(
                    ^^^^^^^^^^^^^^^^^^^^^^
  File "C:\Users\Admin\AppData\Local\Programs\Python\Python312\Lib\site-packages\telegram\request\_httpxrequest.py", line 310, in do_request
    raise TimedOut from err
telegram.error.TimedOut: Timed out
2024-12-21 15:47:02,553 - __main__ - ERROR - Обнаружена ошибка:
Traceback (most recent call last):
  File "C:\Users\Admin\AppData\Local\Programs\Python\Python312\Lib\site-packages\httpx\_transports\default.py", line 72, in map_httpcore_exceptions
    yield
  File "C:\Users\Admin\AppData\Local\Programs\Python\Python312\Lib\site-packages\httpx\_transports\default.py", line 377, in handle_async_request
    resp = await self._pool.handle_async_request(req)
           ^^^^^^^^^^^^^^^^^^^^^^^^^^^^^^^^^^^^^^^^^^
  File "C:\Users\Admin\AppData\Local\Programs\Python\Python312\Lib\site-packages\httpcore\_async\connection_pool.py", line 216, in handle_async_request
    raise exc from None
  File "C:\Users\Admin\AppData\Local\Programs\Python\Python312\Lib\site-packages\httpcore\_async\connection_pool.py", line 196, in handle_async_request
    response = await connection.handle_async_request(
               ^^^^^^^^^^^^^^^^^^^^^^^^^^^^^^^^^^^^^^
  File "C:\Users\Admin\AppData\Local\Programs\Python\Python312\Lib\site-packages\httpcore\_async\connection.py", line 99, in handle_async_request
    raise exc
  File "C:\Users\Admin\AppData\Local\Programs\Python\Python312\Lib\site-packages\httpcore\_async\connection.py", line 76, in handle_async_request
    stream = await self._connect(request)
             ^^^^^^^^^^^^^^^^^^^^^^^^^^^^
  File "C:\Users\Admin\AppData\Local\Programs\Python\Python312\Lib\site-packages\httpcore\_async\connection.py", line 122, in _connect
    stream = await self._network_backend.connect_tcp(**kwargs)
             ^^^^^^^^^^^^^^^^^^^^^^^^^^^^^^^^^^^^^^^^^^^^^^^^^
  File "C:\Users\Admin\AppData\Local\Programs\Python\Python312\Lib\site-packages\httpcore\_backends\auto.py", line 30, in connect_tcp
    return await self._backend.connect_tcp(
           ^^^^^^^^^^^^^^^^^^^^^^^^^^^^^^^^
  File "C:\Users\Admin\AppData\Local\Programs\Python\Python312\Lib\site-packages\httpcore\_backends\anyio.py", line 115, in connect_tcp
    with map_exceptions(exc_map):
  File "C:\Users\Admin\AppData\Local\Programs\Python\Python312\Lib\contextlib.py", line 158, in __exit__
    self.gen.throw(value)
  File "C:\Users\Admin\AppData\Local\Programs\Python\Python312\Lib\site-packages\httpcore\_exceptions.py", line 14, in map_exceptions
    raise to_exc(exc) from exc
httpcore.ConnectError: [Errno 11001] getaddrinfo failed

The above exception was the direct cause of the following exception:

Traceback (most recent call last):
  File "C:\Users\Admin\AppData\Local\Programs\Python\Python312\Lib\site-packages\telegram\request\_httpxrequest.py", line 293, in do_request
    res = await self._client.request(
          ^^^^^^^^^^^^^^^^^^^^^^^^^^^
  File "C:\Users\Admin\AppData\Local\Programs\Python\Python312\Lib\site-packages\httpx\_client.py", line 1585, in request
    return await self.send(request, auth=auth, follow_redirects=follow_redirects)
           ^^^^^^^^^^^^^^^^^^^^^^^^^^^^^^^^^^^^^^^^^^^^^^^^^^^^^^^^^^^^^^^^^^^^^^
  File "C:\Users\Admin\AppData\Local\Programs\Python\Python312\Lib\site-packages\httpx\_client.py", line 1674, in send
    response = await self._send_handling_auth(
               ^^^^^^^^^^^^^^^^^^^^^^^^^^^^^^^
  File "C:\Users\Admin\AppData\Local\Programs\Python\Python312\Lib\site-packages\httpx\_client.py", line 1702, in _send_handling_auth
    response = await self._send_handling_redirects(
               ^^^^^^^^^^^^^^^^^^^^^^^^^^^^^^^^^^^^
  File "C:\Users\Admin\AppData\Local\Programs\Python\Python312\Lib\site-packages\httpx\_client.py", line 1739, in _send_handling_redirects
    response = await self._send_single_request(request)
               ^^^^^^^^^^^^^^^^^^^^^^^^^^^^^^^^^^^^^^^^
  File "C:\Users\Admin\AppData\Local\Programs\Python\Python312\Lib\site-packages\httpx\_client.py", line 1776, in _send_single_request
    response = await transport.handle_async_request(request)
               ^^^^^^^^^^^^^^^^^^^^^^^^^^^^^^^^^^^^^^^^^^^^^
  File "C:\Users\Admin\AppData\Local\Programs\Python\Python312\Lib\site-packages\httpx\_transports\default.py", line 376, in handle_async_request
    with map_httpcore_exceptions():
  File "C:\Users\Admin\AppData\Local\Programs\Python\Python312\Lib\contextlib.py", line 158, in __exit__
    self.gen.throw(value)
  File "C:\Users\Admin\AppData\Local\Programs\Python\Python312\Lib\site-packages\httpx\_transports\default.py", line 89, in map_httpcore_exceptions
    raise mapped_exc(message) from exc
httpx.ConnectError: [Errno 11001] getaddrinfo failed

The above exception was the direct cause of the following exception:

Traceback (most recent call last):
  File "C:\Users\Admin\AppData\Local\Programs\Python\Python312\Lib\site-packages\telegram\ext\_updater.py", line 750, in _network_loop_retry
    if not await do_action():
           ^^^^^^^^^^^^^^^^^
  File "C:\Users\Admin\AppData\Local\Programs\Python\Python312\Lib\site-packages\telegram\ext\_updater.py", line 744, in do_action
    return action_cb_task.result()
           ^^^^^^^^^^^^^^^^^^^^^^^
  File "C:\Users\Admin\AppData\Local\Programs\Python\Python312\Lib\asyncio\futures.py", line 203, in result
    raise self._exception.with_traceback(self._exception_tb)
  File "C:\Users\Admin\AppData\Local\Programs\Python\Python312\Lib\asyncio\tasks.py", line 316, in __step_run_and_handle_result
    result = coro.throw(exc)
             ^^^^^^^^^^^^^^^
  File "C:\Users\Admin\AppData\Local\Programs\Python\Python312\Lib\site-packages\telegram\ext\_updater.py", line 371, in polling_action_cb
    updates = await self.bot.get_updates(
              ^^^^^^^^^^^^^^^^^^^^^^^^^^^
  File "C:\Users\Admin\AppData\Local\Programs\Python\Python312\Lib\site-packages\telegram\ext\_extbot.py", line 650, in get_updates
    updates = await super().get_updates(
              ^^^^^^^^^^^^^^^^^^^^^^^^^^
  File "C:\Users\Admin\AppData\Local\Programs\Python\Python312\Lib\site-packages\telegram\_bot.py", line 4480, in get_updates
    await self._post(
  File "C:\Users\Admin\AppData\Local\Programs\Python\Python312\Lib\site-packages\telegram\_bot.py", line 619, in _post
    return await self._do_post(
           ^^^^^^^^^^^^^^^^^^^^
  File "C:\Users\Admin\AppData\Local\Programs\Python\Python312\Lib\site-packages\telegram\ext\_extbot.py", line 354, in _do_post
    return await super()._do_post(
           ^^^^^^^^^^^^^^^^^^^^^^^
  File "C:\Users\Admin\AppData\Local\Programs\Python\Python312\Lib\site-packages\telegram\_bot.py", line 648, in _do_post
    result = await request.post(
             ^^^^^^^^^^^^^^^^^^^
  File "C:\Users\Admin\AppData\Local\Programs\Python\Python312\Lib\site-packages\telegram\request\_baserequest.py", line 202, in post
    result = await self._request_wrapper(
             ^^^^^^^^^^^^^^^^^^^^^^^^^^^^
  File "C:\Users\Admin\AppData\Local\Programs\Python\Python312\Lib\site-packages\telegram\request\_baserequest.py", line 334, in _request_wrapper
    code, payload = await self.do_request(
                    ^^^^^^^^^^^^^^^^^^^^^^
  File "C:\Users\Admin\AppData\Local\Programs\Python\Python312\Lib\site-packages\telegram\request\_httpxrequest.py", line 317, in do_request
    raise NetworkError(f"httpx.{err.__class__.__name__}: {err}") from err
telegram.error.NetworkError: httpx.ConnectError: [Errno 11001] getaddrinfo failed
2024-12-21 15:47:03,563 - __main__ - ERROR - Обнаружена ошибка:
Traceback (most recent call last):
  File "C:\Users\Admin\AppData\Local\Programs\Python\Python312\Lib\site-packages\httpx\_transports\default.py", line 72, in map_httpcore_exceptions
    yield
  File "C:\Users\Admin\AppData\Local\Programs\Python\Python312\Lib\site-packages\httpx\_transports\default.py", line 377, in handle_async_request
    resp = await self._pool.handle_async_request(req)
           ^^^^^^^^^^^^^^^^^^^^^^^^^^^^^^^^^^^^^^^^^^
  File "C:\Users\Admin\AppData\Local\Programs\Python\Python312\Lib\site-packages\httpcore\_async\connection_pool.py", line 216, in handle_async_request
    raise exc from None
  File "C:\Users\Admin\AppData\Local\Programs\Python\Python312\Lib\site-packages\httpcore\_async\connection_pool.py", line 196, in handle_async_request
    response = await connection.handle_async_request(
               ^^^^^^^^^^^^^^^^^^^^^^^^^^^^^^^^^^^^^^
  File "C:\Users\Admin\AppData\Local\Programs\Python\Python312\Lib\site-packages\httpcore\_async\connection.py", line 99, in handle_async_request
    raise exc
  File "C:\Users\Admin\AppData\Local\Programs\Python\Python312\Lib\site-packages\httpcore\_async\connection.py", line 76, in handle_async_request
    stream = await self._connect(request)
             ^^^^^^^^^^^^^^^^^^^^^^^^^^^^
  File "C:\Users\Admin\AppData\Local\Programs\Python\Python312\Lib\site-packages\httpcore\_async\connection.py", line 122, in _connect
    stream = await self._network_backend.connect_tcp(**kwargs)
             ^^^^^^^^^^^^^^^^^^^^^^^^^^^^^^^^^^^^^^^^^^^^^^^^^
  File "C:\Users\Admin\AppData\Local\Programs\Python\Python312\Lib\site-packages\httpcore\_backends\auto.py", line 30, in connect_tcp
    return await self._backend.connect_tcp(
           ^^^^^^^^^^^^^^^^^^^^^^^^^^^^^^^^
  File "C:\Users\Admin\AppData\Local\Programs\Python\Python312\Lib\site-packages\httpcore\_backends\anyio.py", line 115, in connect_tcp
    with map_exceptions(exc_map):
  File "C:\Users\Admin\AppData\Local\Programs\Python\Python312\Lib\contextlib.py", line 158, in __exit__
    self.gen.throw(value)
  File "C:\Users\Admin\AppData\Local\Programs\Python\Python312\Lib\site-packages\httpcore\_exceptions.py", line 14, in map_exceptions
    raise to_exc(exc) from exc
httpcore.ConnectError: [Errno 11001] getaddrinfo failed

The above exception was the direct cause of the following exception:

Traceback (most recent call last):
  File "C:\Users\Admin\AppData\Local\Programs\Python\Python312\Lib\site-packages\telegram\request\_httpxrequest.py", line 293, in do_request
    res = await self._client.request(
          ^^^^^^^^^^^^^^^^^^^^^^^^^^^
  File "C:\Users\Admin\AppData\Local\Programs\Python\Python312\Lib\site-packages\httpx\_client.py", line 1585, in request
    return await self.send(request, auth=auth, follow_redirects=follow_redirects)
           ^^^^^^^^^^^^^^^^^^^^^^^^^^^^^^^^^^^^^^^^^^^^^^^^^^^^^^^^^^^^^^^^^^^^^^
  File "C:\Users\Admin\AppData\Local\Programs\Python\Python312\Lib\site-packages\httpx\_client.py", line 1674, in send
    response = await self._send_handling_auth(
               ^^^^^^^^^^^^^^^^^^^^^^^^^^^^^^^
  File "C:\Users\Admin\AppData\Local\Programs\Python\Python312\Lib\site-packages\httpx\_client.py", line 1702, in _send_handling_auth
    response = await self._send_handling_redirects(
               ^^^^^^^^^^^^^^^^^^^^^^^^^^^^^^^^^^^^
  File "C:\Users\Admin\AppData\Local\Programs\Python\Python312\Lib\site-packages\httpx\_client.py", line 1739, in _send_handling_redirects
    response = await self._send_single_request(request)
               ^^^^^^^^^^^^^^^^^^^^^^^^^^^^^^^^^^^^^^^^
  File "C:\Users\Admin\AppData\Local\Programs\Python\Python312\Lib\site-packages\httpx\_client.py", line 1776, in _send_single_request
    response = await transport.handle_async_request(request)
               ^^^^^^^^^^^^^^^^^^^^^^^^^^^^^^^^^^^^^^^^^^^^^
  File "C:\Users\Admin\AppData\Local\Programs\Python\Python312\Lib\site-packages\httpx\_transports\default.py", line 376, in handle_async_request
    with map_httpcore_exceptions():
  File "C:\Users\Admin\AppData\Local\Programs\Python\Python312\Lib\contextlib.py", line 158, in __exit__
    self.gen.throw(value)
  File "C:\Users\Admin\AppData\Local\Programs\Python\Python312\Lib\site-packages\httpx\_transports\default.py", line 89, in map_httpcore_exceptions
    raise mapped_exc(message) from exc
httpx.ConnectError: [Errno 11001] getaddrinfo failed

The above exception was the direct cause of the following exception:

Traceback (most recent call last):
  File "C:\Users\Admin\AppData\Local\Programs\Python\Python312\Lib\site-packages\telegram\ext\_updater.py", line 750, in _network_loop_retry
    if not await do_action():
           ^^^^^^^^^^^^^^^^^
  File "C:\Users\Admin\AppData\Local\Programs\Python\Python312\Lib\site-packages\telegram\ext\_updater.py", line 744, in do_action
    return action_cb_task.result()
           ^^^^^^^^^^^^^^^^^^^^^^^
  File "C:\Users\Admin\AppData\Local\Programs\Python\Python312\Lib\asyncio\futures.py", line 203, in result
    raise self._exception.with_traceback(self._exception_tb)
  File "C:\Users\Admin\AppData\Local\Programs\Python\Python312\Lib\asyncio\tasks.py", line 316, in __step_run_and_handle_result
    result = coro.throw(exc)
             ^^^^^^^^^^^^^^^
  File "C:\Users\Admin\AppData\Local\Programs\Python\Python312\Lib\site-packages\telegram\ext\_updater.py", line 371, in polling_action_cb
    updates = await self.bot.get_updates(
              ^^^^^^^^^^^^^^^^^^^^^^^^^^^
  File "C:\Users\Admin\AppData\Local\Programs\Python\Python312\Lib\site-packages\telegram\ext\_extbot.py", line 650, in get_updates
    updates = await super().get_updates(
              ^^^^^^^^^^^^^^^^^^^^^^^^^^
  File "C:\Users\Admin\AppData\Local\Programs\Python\Python312\Lib\site-packages\telegram\_bot.py", line 4480, in get_updates
    await self._post(
  File "C:\Users\Admin\AppData\Local\Programs\Python\Python312\Lib\site-packages\telegram\_bot.py", line 619, in _post
    return await self._do_post(
           ^^^^^^^^^^^^^^^^^^^^
  File "C:\Users\Admin\AppData\Local\Programs\Python\Python312\Lib\site-packages\telegram\ext\_extbot.py", line 354, in _do_post
    return await super()._do_post(
           ^^^^^^^^^^^^^^^^^^^^^^^
  File "C:\Users\Admin\AppData\Local\Programs\Python\Python312\Lib\site-packages\telegram\_bot.py", line 648, in _do_post
    result = await request.post(
             ^^^^^^^^^^^^^^^^^^^
  File "C:\Users\Admin\AppData\Local\Programs\Python\Python312\Lib\site-packages\telegram\request\_baserequest.py", line 202, in post
    result = await self._request_wrapper(
             ^^^^^^^^^^^^^^^^^^^^^^^^^^^^
  File "C:\Users\Admin\AppData\Local\Programs\Python\Python312\Lib\site-packages\telegram\request\_baserequest.py", line 334, in _request_wrapper
    code, payload = await self.do_request(
                    ^^^^^^^^^^^^^^^^^^^^^^
  File "C:\Users\Admin\AppData\Local\Programs\Python\Python312\Lib\site-packages\telegram\request\_httpxrequest.py", line 317, in do_request
    raise NetworkError(f"httpx.{err.__class__.__name__}: {err}") from err
telegram.error.NetworkError: httpx.ConnectError: [Errno 11001] getaddrinfo failed
2024-12-21 15:47:05,068 - __main__ - ERROR - Обнаружена ошибка:
Traceback (most recent call last):
  File "C:\Users\Admin\AppData\Local\Programs\Python\Python312\Lib\site-packages\httpx\_transports\default.py", line 72, in map_httpcore_exceptions
    yield
  File "C:\Users\Admin\AppData\Local\Programs\Python\Python312\Lib\site-packages\httpx\_transports\default.py", line 377, in handle_async_request
    resp = await self._pool.handle_async_request(req)
           ^^^^^^^^^^^^^^^^^^^^^^^^^^^^^^^^^^^^^^^^^^
  File "C:\Users\Admin\AppData\Local\Programs\Python\Python312\Lib\site-packages\httpcore\_async\connection_pool.py", line 216, in handle_async_request
    raise exc from None
  File "C:\Users\Admin\AppData\Local\Programs\Python\Python312\Lib\site-packages\httpcore\_async\connection_pool.py", line 196, in handle_async_request
    response = await connection.handle_async_request(
               ^^^^^^^^^^^^^^^^^^^^^^^^^^^^^^^^^^^^^^
  File "C:\Users\Admin\AppData\Local\Programs\Python\Python312\Lib\site-packages\httpcore\_async\connection.py", line 99, in handle_async_request
    raise exc
  File "C:\Users\Admin\AppData\Local\Programs\Python\Python312\Lib\site-packages\httpcore\_async\connection.py", line 76, in handle_async_request
    stream = await self._connect(request)
             ^^^^^^^^^^^^^^^^^^^^^^^^^^^^
  File "C:\Users\Admin\AppData\Local\Programs\Python\Python312\Lib\site-packages\httpcore\_async\connection.py", line 122, in _connect
    stream = await self._network_backend.connect_tcp(**kwargs)
             ^^^^^^^^^^^^^^^^^^^^^^^^^^^^^^^^^^^^^^^^^^^^^^^^^
  File "C:\Users\Admin\AppData\Local\Programs\Python\Python312\Lib\site-packages\httpcore\_backends\auto.py", line 30, in connect_tcp
    return await self._backend.connect_tcp(
           ^^^^^^^^^^^^^^^^^^^^^^^^^^^^^^^^
  File "C:\Users\Admin\AppData\Local\Programs\Python\Python312\Lib\site-packages\httpcore\_backends\anyio.py", line 115, in connect_tcp
    with map_exceptions(exc_map):
  File "C:\Users\Admin\AppData\Local\Programs\Python\Python312\Lib\contextlib.py", line 158, in __exit__
    self.gen.throw(value)
  File "C:\Users\Admin\AppData\Local\Programs\Python\Python312\Lib\site-packages\httpcore\_exceptions.py", line 14, in map_exceptions
    raise to_exc(exc) from exc
httpcore.ConnectError: [Errno 11001] getaddrinfo failed

The above exception was the direct cause of the following exception:

Traceback (most recent call last):
  File "C:\Users\Admin\AppData\Local\Programs\Python\Python312\Lib\site-packages\telegram\request\_httpxrequest.py", line 293, in do_request
    res = await self._client.request(
          ^^^^^^^^^^^^^^^^^^^^^^^^^^^
  File "C:\Users\Admin\AppData\Local\Programs\Python\Python312\Lib\site-packages\httpx\_client.py", line 1585, in request
    return await self.send(request, auth=auth, follow_redirects=follow_redirects)
           ^^^^^^^^^^^^^^^^^^^^^^^^^^^^^^^^^^^^^^^^^^^^^^^^^^^^^^^^^^^^^^^^^^^^^^
  File "C:\Users\Admin\AppData\Local\Programs\Python\Python312\Lib\site-packages\httpx\_client.py", line 1674, in send
    response = await self._send_handling_auth(
               ^^^^^^^^^^^^^^^^^^^^^^^^^^^^^^^
  File "C:\Users\Admin\AppData\Local\Programs\Python\Python312\Lib\site-packages\httpx\_client.py", line 1702, in _send_handling_auth
    response = await self._send_handling_redirects(
               ^^^^^^^^^^^^^^^^^^^^^^^^^^^^^^^^^^^^
  File "C:\Users\Admin\AppData\Local\Programs\Python\Python312\Lib\site-packages\httpx\_client.py", line 1739, in _send_handling_redirects
    response = await self._send_single_request(request)
               ^^^^^^^^^^^^^^^^^^^^^^^^^^^^^^^^^^^^^^^^
  File "C:\Users\Admin\AppData\Local\Programs\Python\Python312\Lib\site-packages\httpx\_client.py", line 1776, in _send_single_request
    response = await transport.handle_async_request(request)
               ^^^^^^^^^^^^^^^^^^^^^^^^^^^^^^^^^^^^^^^^^^^^^
  File "C:\Users\Admin\AppData\Local\Programs\Python\Python312\Lib\site-packages\httpx\_transports\default.py", line 376, in handle_async_request
    with map_httpcore_exceptions():
  File "C:\Users\Admin\AppData\Local\Programs\Python\Python312\Lib\contextlib.py", line 158, in __exit__
    self.gen.throw(value)
  File "C:\Users\Admin\AppData\Local\Programs\Python\Python312\Lib\site-packages\httpx\_transports\default.py", line 89, in map_httpcore_exceptions
    raise mapped_exc(message) from exc
httpx.ConnectError: [Errno 11001] getaddrinfo failed

The above exception was the direct cause of the following exception:

Traceback (most recent call last):
  File "C:\Users\Admin\AppData\Local\Programs\Python\Python312\Lib\site-packages\telegram\ext\_updater.py", line 750, in _network_loop_retry
    if not await do_action():
           ^^^^^^^^^^^^^^^^^
  File "C:\Users\Admin\AppData\Local\Programs\Python\Python312\Lib\site-packages\telegram\ext\_updater.py", line 744, in do_action
    return action_cb_task.result()
           ^^^^^^^^^^^^^^^^^^^^^^^
  File "C:\Users\Admin\AppData\Local\Programs\Python\Python312\Lib\asyncio\futures.py", line 203, in result
    raise self._exception.with_traceback(self._exception_tb)
  File "C:\Users\Admin\AppData\Local\Programs\Python\Python312\Lib\asyncio\tasks.py", line 316, in __step_run_and_handle_result
    result = coro.throw(exc)
             ^^^^^^^^^^^^^^^
  File "C:\Users\Admin\AppData\Local\Programs\Python\Python312\Lib\site-packages\telegram\ext\_updater.py", line 371, in polling_action_cb
    updates = await self.bot.get_updates(
              ^^^^^^^^^^^^^^^^^^^^^^^^^^^
  File "C:\Users\Admin\AppData\Local\Programs\Python\Python312\Lib\site-packages\telegram\ext\_extbot.py", line 650, in get_updates
    updates = await super().get_updates(
              ^^^^^^^^^^^^^^^^^^^^^^^^^^
  File "C:\Users\Admin\AppData\Local\Programs\Python\Python312\Lib\site-packages\telegram\_bot.py", line 4480, in get_updates
    await self._post(
  File "C:\Users\Admin\AppData\Local\Programs\Python\Python312\Lib\site-packages\telegram\_bot.py", line 619, in _post
    return await self._do_post(
           ^^^^^^^^^^^^^^^^^^^^
  File "C:\Users\Admin\AppData\Local\Programs\Python\Python312\Lib\site-packages\telegram\ext\_extbot.py", line 354, in _do_post
    return await super()._do_post(
           ^^^^^^^^^^^^^^^^^^^^^^^
  File "C:\Users\Admin\AppData\Local\Programs\Python\Python312\Lib\site-packages\telegram\_bot.py", line 648, in _do_post
    result = await request.post(
             ^^^^^^^^^^^^^^^^^^^
  File "C:\Users\Admin\AppData\Local\Programs\Python\Python312\Lib\site-packages\telegram\request\_baserequest.py", line 202, in post
    result = await self._request_wrapper(
             ^^^^^^^^^^^^^^^^^^^^^^^^^^^^
  File "C:\Users\Admin\AppData\Local\Programs\Python\Python312\Lib\site-packages\telegram\request\_baserequest.py", line 334, in _request_wrapper
    code, payload = await self.do_request(
                    ^^^^^^^^^^^^^^^^^^^^^^
  File "C:\Users\Admin\AppData\Local\Programs\Python\Python312\Lib\site-packages\telegram\request\_httpxrequest.py", line 317, in do_request
    raise NetworkError(f"httpx.{err.__class__.__name__}: {err}") from err
telegram.error.NetworkError: httpx.ConnectError: [Errno 11001] getaddrinfo failed
2024-12-21 15:47:07,311 - __main__ - ERROR - Обнаружена ошибка:
Traceback (most recent call last):
  File "C:\Users\Admin\AppData\Local\Programs\Python\Python312\Lib\site-packages\httpx\_transports\default.py", line 72, in map_httpcore_exceptions
    yield
  File "C:\Users\Admin\AppData\Local\Programs\Python\Python312\Lib\site-packages\httpx\_transports\default.py", line 377, in handle_async_request
    resp = await self._pool.handle_async_request(req)
           ^^^^^^^^^^^^^^^^^^^^^^^^^^^^^^^^^^^^^^^^^^
  File "C:\Users\Admin\AppData\Local\Programs\Python\Python312\Lib\site-packages\httpcore\_async\connection_pool.py", line 216, in handle_async_request
    raise exc from None
  File "C:\Users\Admin\AppData\Local\Programs\Python\Python312\Lib\site-packages\httpcore\_async\connection_pool.py", line 196, in handle_async_request
    response = await connection.handle_async_request(
               ^^^^^^^^^^^^^^^^^^^^^^^^^^^^^^^^^^^^^^
  File "C:\Users\Admin\AppData\Local\Programs\Python\Python312\Lib\site-packages\httpcore\_async\connection.py", line 99, in handle_async_request
    raise exc
  File "C:\Users\Admin\AppData\Local\Programs\Python\Python312\Lib\site-packages\httpcore\_async\connection.py", line 76, in handle_async_request
    stream = await self._connect(request)
             ^^^^^^^^^^^^^^^^^^^^^^^^^^^^
  File "C:\Users\Admin\AppData\Local\Programs\Python\Python312\Lib\site-packages\httpcore\_async\connection.py", line 122, in _connect
    stream = await self._network_backend.connect_tcp(**kwargs)
             ^^^^^^^^^^^^^^^^^^^^^^^^^^^^^^^^^^^^^^^^^^^^^^^^^
  File "C:\Users\Admin\AppData\Local\Programs\Python\Python312\Lib\site-packages\httpcore\_backends\auto.py", line 30, in connect_tcp
    return await self._backend.connect_tcp(
           ^^^^^^^^^^^^^^^^^^^^^^^^^^^^^^^^
  File "C:\Users\Admin\AppData\Local\Programs\Python\Python312\Lib\site-packages\httpcore\_backends\anyio.py", line 115, in connect_tcp
    with map_exceptions(exc_map):
  File "C:\Users\Admin\AppData\Local\Programs\Python\Python312\Lib\contextlib.py", line 158, in __exit__
    self.gen.throw(value)
  File "C:\Users\Admin\AppData\Local\Programs\Python\Python312\Lib\site-packages\httpcore\_exceptions.py", line 14, in map_exceptions
    raise to_exc(exc) from exc
httpcore.ConnectError: [Errno 11001] getaddrinfo failed

The above exception was the direct cause of the following exception:

Traceback (most recent call last):
  File "C:\Users\Admin\AppData\Local\Programs\Python\Python312\Lib\site-packages\telegram\request\_httpxrequest.py", line 293, in do_request
    res = await self._client.request(
          ^^^^^^^^^^^^^^^^^^^^^^^^^^^
  File "C:\Users\Admin\AppData\Local\Programs\Python\Python312\Lib\site-packages\httpx\_client.py", line 1585, in request
    return await self.send(request, auth=auth, follow_redirects=follow_redirects)
           ^^^^^^^^^^^^^^^^^^^^^^^^^^^^^^^^^^^^^^^^^^^^^^^^^^^^^^^^^^^^^^^^^^^^^^
  File "C:\Users\Admin\AppData\Local\Programs\Python\Python312\Lib\site-packages\httpx\_client.py", line 1674, in send
    response = await self._send_handling_auth(
               ^^^^^^^^^^^^^^^^^^^^^^^^^^^^^^^
  File "C:\Users\Admin\AppData\Local\Programs\Python\Python312\Lib\site-packages\httpx\_client.py", line 1702, in _send_handling_auth
    response = await self._send_handling_redirects(
               ^^^^^^^^^^^^^^^^^^^^^^^^^^^^^^^^^^^^
  File "C:\Users\Admin\AppData\Local\Programs\Python\Python312\Lib\site-packages\httpx\_client.py", line 1739, in _send_handling_redirects
    response = await self._send_single_request(request)
               ^^^^^^^^^^^^^^^^^^^^^^^^^^^^^^^^^^^^^^^^
  File "C:\Users\Admin\AppData\Local\Programs\Python\Python312\Lib\site-packages\httpx\_client.py", line 1776, in _send_single_request
    response = await transport.handle_async_request(request)
               ^^^^^^^^^^^^^^^^^^^^^^^^^^^^^^^^^^^^^^^^^^^^^
  File "C:\Users\Admin\AppData\Local\Programs\Python\Python312\Lib\site-packages\httpx\_transports\default.py", line 376, in handle_async_request
    with map_httpcore_exceptions():
  File "C:\Users\Admin\AppData\Local\Programs\Python\Python312\Lib\contextlib.py", line 158, in __exit__
    self.gen.throw(value)
  File "C:\Users\Admin\AppData\Local\Programs\Python\Python312\Lib\site-packages\httpx\_transports\default.py", line 89, in map_httpcore_exceptions
    raise mapped_exc(message) from exc
httpx.ConnectError: [Errno 11001] getaddrinfo failed

The above exception was the direct cause of the following exception:

Traceback (most recent call last):
  File "C:\Users\Admin\AppData\Local\Programs\Python\Python312\Lib\site-packages\telegram\ext\_updater.py", line 750, in _network_loop_retry
    if not await do_action():
           ^^^^^^^^^^^^^^^^^
  File "C:\Users\Admin\AppData\Local\Programs\Python\Python312\Lib\site-packages\telegram\ext\_updater.py", line 744, in do_action
    return action_cb_task.result()
           ^^^^^^^^^^^^^^^^^^^^^^^
  File "C:\Users\Admin\AppData\Local\Programs\Python\Python312\Lib\asyncio\futures.py", line 203, in result
    raise self._exception.with_traceback(self._exception_tb)
  File "C:\Users\Admin\AppData\Local\Programs\Python\Python312\Lib\asyncio\tasks.py", line 316, in __step_run_and_handle_result
    result = coro.throw(exc)
             ^^^^^^^^^^^^^^^
  File "C:\Users\Admin\AppData\Local\Programs\Python\Python312\Lib\site-packages\telegram\ext\_updater.py", line 371, in polling_action_cb
    updates = await self.bot.get_updates(
              ^^^^^^^^^^^^^^^^^^^^^^^^^^^
  File "C:\Users\Admin\AppData\Local\Programs\Python\Python312\Lib\site-packages\telegram\ext\_extbot.py", line 650, in get_updates
    updates = await super().get_updates(
              ^^^^^^^^^^^^^^^^^^^^^^^^^^
  File "C:\Users\Admin\AppData\Local\Programs\Python\Python312\Lib\site-packages\telegram\_bot.py", line 4480, in get_updates
    await self._post(
  File "C:\Users\Admin\AppData\Local\Programs\Python\Python312\Lib\site-packages\telegram\_bot.py", line 619, in _post
    return await self._do_post(
           ^^^^^^^^^^^^^^^^^^^^
  File "C:\Users\Admin\AppData\Local\Programs\Python\Python312\Lib\site-packages\telegram\ext\_extbot.py", line 354, in _do_post
    return await super()._do_post(
           ^^^^^^^^^^^^^^^^^^^^^^^
  File "C:\Users\Admin\AppData\Local\Programs\Python\Python312\Lib\site-packages\telegram\_bot.py", line 648, in _do_post
    result = await request.post(
             ^^^^^^^^^^^^^^^^^^^
  File "C:\Users\Admin\AppData\Local\Programs\Python\Python312\Lib\site-packages\telegram\request\_baserequest.py", line 202, in post
    result = await self._request_wrapper(
             ^^^^^^^^^^^^^^^^^^^^^^^^^^^^
  File "C:\Users\Admin\AppData\Local\Programs\Python\Python312\Lib\site-packages\telegram\request\_baserequest.py", line 334, in _request_wrapper
    code, payload = await self.do_request(
                    ^^^^^^^^^^^^^^^^^^^^^^
  File "C:\Users\Admin\AppData\Local\Programs\Python\Python312\Lib\site-packages\telegram\request\_httpxrequest.py", line 317, in do_request
    raise NetworkError(f"httpx.{err.__class__.__name__}: {err}") from err
telegram.error.NetworkError: httpx.ConnectError: [Errno 11001] getaddrinfo failed
2024-12-21 15:47:14,693 - __main__ - ERROR - Обнаружена ошибка:
Traceback (most recent call last):
  File "C:\Users\Admin\AppData\Local\Programs\Python\Python312\Lib\site-packages\httpx\_transports\default.py", line 72, in map_httpcore_exceptions
    yield
  File "C:\Users\Admin\AppData\Local\Programs\Python\Python312\Lib\site-packages\httpx\_transports\default.py", line 377, in handle_async_request
    resp = await self._pool.handle_async_request(req)
           ^^^^^^^^^^^^^^^^^^^^^^^^^^^^^^^^^^^^^^^^^^
  File "C:\Users\Admin\AppData\Local\Programs\Python\Python312\Lib\site-packages\httpcore\_async\connection_pool.py", line 216, in handle_async_request
    raise exc from None
  File "C:\Users\Admin\AppData\Local\Programs\Python\Python312\Lib\site-packages\httpcore\_async\connection_pool.py", line 196, in handle_async_request
    response = await connection.handle_async_request(
               ^^^^^^^^^^^^^^^^^^^^^^^^^^^^^^^^^^^^^^
  File "C:\Users\Admin\AppData\Local\Programs\Python\Python312\Lib\site-packages\httpcore\_async\connection.py", line 99, in handle_async_request
    raise exc
  File "C:\Users\Admin\AppData\Local\Programs\Python\Python312\Lib\site-packages\httpcore\_async\connection.py", line 76, in handle_async_request
    stream = await self._connect(request)
             ^^^^^^^^^^^^^^^^^^^^^^^^^^^^
  File "C:\Users\Admin\AppData\Local\Programs\Python\Python312\Lib\site-packages\httpcore\_async\connection.py", line 122, in _connect
    stream = await self._network_backend.connect_tcp(**kwargs)
             ^^^^^^^^^^^^^^^^^^^^^^^^^^^^^^^^^^^^^^^^^^^^^^^^^
  File "C:\Users\Admin\AppData\Local\Programs\Python\Python312\Lib\site-packages\httpcore\_backends\auto.py", line 30, in connect_tcp
    return await self._backend.connect_tcp(
           ^^^^^^^^^^^^^^^^^^^^^^^^^^^^^^^^
  File "C:\Users\Admin\AppData\Local\Programs\Python\Python312\Lib\site-packages\httpcore\_backends\anyio.py", line 115, in connect_tcp
    with map_exceptions(exc_map):
  File "C:\Users\Admin\AppData\Local\Programs\Python\Python312\Lib\contextlib.py", line 158, in __exit__
    self.gen.throw(value)
  File "C:\Users\Admin\AppData\Local\Programs\Python\Python312\Lib\site-packages\httpcore\_exceptions.py", line 14, in map_exceptions
    raise to_exc(exc) from exc
httpcore.ConnectError: [Errno 11001] getaddrinfo failed

The above exception was the direct cause of the following exception:

Traceback (most recent call last):
  File "C:\Users\Admin\AppData\Local\Programs\Python\Python312\Lib\site-packages\telegram\request\_httpxrequest.py", line 293, in do_request
    res = await self._client.request(
          ^^^^^^^^^^^^^^^^^^^^^^^^^^^
  File "C:\Users\Admin\AppData\Local\Programs\Python\Python312\Lib\site-packages\httpx\_client.py", line 1585, in request
    return await self.send(request, auth=auth, follow_redirects=follow_redirects)
           ^^^^^^^^^^^^^^^^^^^^^^^^^^^^^^^^^^^^^^^^^^^^^^^^^^^^^^^^^^^^^^^^^^^^^^
  File "C:\Users\Admin\AppData\Local\Programs\Python\Python312\Lib\site-packages\httpx\_client.py", line 1674, in send
    response = await self._send_handling_auth(
               ^^^^^^^^^^^^^^^^^^^^^^^^^^^^^^^
  File "C:\Users\Admin\AppData\Local\Programs\Python\Python312\Lib\site-packages\httpx\_client.py", line 1702, in _send_handling_auth
    response = await self._send_handling_redirects(
               ^^^^^^^^^^^^^^^^^^^^^^^^^^^^^^^^^^^^
  File "C:\Users\Admin\AppData\Local\Programs\Python\Python312\Lib\site-packages\httpx\_client.py", line 1739, in _send_handling_redirects
    response = await self._send_single_request(request)
               ^^^^^^^^^^^^^^^^^^^^^^^^^^^^^^^^^^^^^^^^
  File "C:\Users\Admin\AppData\Local\Programs\Python\Python312\Lib\site-packages\httpx\_client.py", line 1776, in _send_single_request
    response = await transport.handle_async_request(request)
               ^^^^^^^^^^^^^^^^^^^^^^^^^^^^^^^^^^^^^^^^^^^^^
  File "C:\Users\Admin\AppData\Local\Programs\Python\Python312\Lib\site-packages\httpx\_transports\default.py", line 376, in handle_async_request
    with map_httpcore_exceptions():
  File "C:\Users\Admin\AppData\Local\Programs\Python\Python312\Lib\contextlib.py", line 158, in __exit__
    self.gen.throw(value)
  File "C:\Users\Admin\AppData\Local\Programs\Python\Python312\Lib\site-packages\httpx\_transports\default.py", line 89, in map_httpcore_exceptions
    raise mapped_exc(message) from exc
httpx.ConnectError: [Errno 11001] getaddrinfo failed

The above exception was the direct cause of the following exception:

Traceback (most recent call last):
  File "C:\Users\Admin\AppData\Local\Programs\Python\Python312\Lib\site-packages\telegram\ext\_updater.py", line 750, in _network_loop_retry
    if not await do_action():
           ^^^^^^^^^^^^^^^^^
  File "C:\Users\Admin\AppData\Local\Programs\Python\Python312\Lib\site-packages\telegram\ext\_updater.py", line 744, in do_action
    return action_cb_task.result()
           ^^^^^^^^^^^^^^^^^^^^^^^
  File "C:\Users\Admin\AppData\Local\Programs\Python\Python312\Lib\asyncio\futures.py", line 203, in result
    raise self._exception.with_traceback(self._exception_tb)
  File "C:\Users\Admin\AppData\Local\Programs\Python\Python312\Lib\asyncio\tasks.py", line 316, in __step_run_and_handle_result
    result = coro.throw(exc)
             ^^^^^^^^^^^^^^^
  File "C:\Users\Admin\AppData\Local\Programs\Python\Python312\Lib\site-packages\telegram\ext\_updater.py", line 371, in polling_action_cb
    updates = await self.bot.get_updates(
              ^^^^^^^^^^^^^^^^^^^^^^^^^^^
  File "C:\Users\Admin\AppData\Local\Programs\Python\Python312\Lib\site-packages\telegram\ext\_extbot.py", line 650, in get_updates
    updates = await super().get_updates(
              ^^^^^^^^^^^^^^^^^^^^^^^^^^
  File "C:\Users\Admin\AppData\Local\Programs\Python\Python312\Lib\site-packages\telegram\_bot.py", line 4480, in get_updates
    await self._post(
  File "C:\Users\Admin\AppData\Local\Programs\Python\Python312\Lib\site-packages\telegram\_bot.py", line 619, in _post
    return await self._do_post(
           ^^^^^^^^^^^^^^^^^^^^
  File "C:\Users\Admin\AppData\Local\Programs\Python\Python312\Lib\site-packages\telegram\ext\_extbot.py", line 354, in _do_post
    return await super()._do_post(
           ^^^^^^^^^^^^^^^^^^^^^^^
  File "C:\Users\Admin\AppData\Local\Programs\Python\Python312\Lib\site-packages\telegram\_bot.py", line 648, in _do_post
    result = await request.post(
             ^^^^^^^^^^^^^^^^^^^
  File "C:\Users\Admin\AppData\Local\Programs\Python\Python312\Lib\site-packages\telegram\request\_baserequest.py", line 202, in post
    result = await self._request_wrapper(
             ^^^^^^^^^^^^^^^^^^^^^^^^^^^^
  File "C:\Users\Admin\AppData\Local\Programs\Python\Python312\Lib\site-packages\telegram\request\_baserequest.py", line 334, in _request_wrapper
    code, payload = await self.do_request(
                    ^^^^^^^^^^^^^^^^^^^^^^
  File "C:\Users\Admin\AppData\Local\Programs\Python\Python312\Lib\site-packages\telegram\request\_httpxrequest.py", line 317, in do_request
    raise NetworkError(f"httpx.{err.__class__.__name__}: {err}") from err
telegram.error.NetworkError: httpx.ConnectError: [Errno 11001] getaddrinfo failed
2024-12-21 15:47:19,747 - __main__ - ERROR - Обнаружена ошибка:
Traceback (most recent call last):
  File "C:\Users\Admin\AppData\Local\Programs\Python\Python312\Lib\site-packages\httpx\_transports\default.py", line 72, in map_httpcore_exceptions
    yield
  File "C:\Users\Admin\AppData\Local\Programs\Python\Python312\Lib\site-packages\httpx\_transports\default.py", line 377, in handle_async_request
    resp = await self._pool.handle_async_request(req)
           ^^^^^^^^^^^^^^^^^^^^^^^^^^^^^^^^^^^^^^^^^^
  File "C:\Users\Admin\AppData\Local\Programs\Python\Python312\Lib\site-packages\httpcore\_async\connection_pool.py", line 216, in handle_async_request
    raise exc from None
  File "C:\Users\Admin\AppData\Local\Programs\Python\Python312\Lib\site-packages\httpcore\_async\connection_pool.py", line 196, in handle_async_request
    response = await connection.handle_async_request(
               ^^^^^^^^^^^^^^^^^^^^^^^^^^^^^^^^^^^^^^
  File "C:\Users\Admin\AppData\Local\Programs\Python\Python312\Lib\site-packages\httpcore\_async\connection.py", line 99, in handle_async_request
    raise exc
  File "C:\Users\Admin\AppData\Local\Programs\Python\Python312\Lib\site-packages\httpcore\_async\connection.py", line 76, in handle_async_request
    stream = await self._connect(request)
             ^^^^^^^^^^^^^^^^^^^^^^^^^^^^
  File "C:\Users\Admin\AppData\Local\Programs\Python\Python312\Lib\site-packages\httpcore\_async\connection.py", line 122, in _connect
    stream = await self._network_backend.connect_tcp(**kwargs)
             ^^^^^^^^^^^^^^^^^^^^^^^^^^^^^^^^^^^^^^^^^^^^^^^^^
  File "C:\Users\Admin\AppData\Local\Programs\Python\Python312\Lib\site-packages\httpcore\_backends\auto.py", line 30, in connect_tcp
    return await self._backend.connect_tcp(
           ^^^^^^^^^^^^^^^^^^^^^^^^^^^^^^^^
  File "C:\Users\Admin\AppData\Local\Programs\Python\Python312\Lib\site-packages\httpcore\_backends\anyio.py", line 115, in connect_tcp
    with map_exceptions(exc_map):
  File "C:\Users\Admin\AppData\Local\Programs\Python\Python312\Lib\contextlib.py", line 158, in __exit__
    self.gen.throw(value)
  File "C:\Users\Admin\AppData\Local\Programs\Python\Python312\Lib\site-packages\httpcore\_exceptions.py", line 14, in map_exceptions
    raise to_exc(exc) from exc
httpcore.ConnectError: [Errno 11001] getaddrinfo failed

The above exception was the direct cause of the following exception:

Traceback (most recent call last):
  File "C:\Users\Admin\AppData\Local\Programs\Python\Python312\Lib\site-packages\telegram\request\_httpxrequest.py", line 293, in do_request
    res = await self._client.request(
          ^^^^^^^^^^^^^^^^^^^^^^^^^^^
  File "C:\Users\Admin\AppData\Local\Programs\Python\Python312\Lib\site-packages\httpx\_client.py", line 1585, in request
    return await self.send(request, auth=auth, follow_redirects=follow_redirects)
           ^^^^^^^^^^^^^^^^^^^^^^^^^^^^^^^^^^^^^^^^^^^^^^^^^^^^^^^^^^^^^^^^^^^^^^
  File "C:\Users\Admin\AppData\Local\Programs\Python\Python312\Lib\site-packages\httpx\_client.py", line 1674, in send
    response = await self._send_handling_auth(
               ^^^^^^^^^^^^^^^^^^^^^^^^^^^^^^^
  File "C:\Users\Admin\AppData\Local\Programs\Python\Python312\Lib\site-packages\httpx\_client.py", line 1702, in _send_handling_auth
    response = await self._send_handling_redirects(
               ^^^^^^^^^^^^^^^^^^^^^^^^^^^^^^^^^^^^
  File "C:\Users\Admin\AppData\Local\Programs\Python\Python312\Lib\site-packages\httpx\_client.py", line 1739, in _send_handling_redirects
    response = await self._send_single_request(request)
               ^^^^^^^^^^^^^^^^^^^^^^^^^^^^^^^^^^^^^^^^
  File "C:\Users\Admin\AppData\Local\Programs\Python\Python312\Lib\site-packages\httpx\_client.py", line 1776, in _send_single_request
    response = await transport.handle_async_request(request)
               ^^^^^^^^^^^^^^^^^^^^^^^^^^^^^^^^^^^^^^^^^^^^^
  File "C:\Users\Admin\AppData\Local\Programs\Python\Python312\Lib\site-packages\httpx\_transports\default.py", line 376, in handle_async_request
    with map_httpcore_exceptions():
  File "C:\Users\Admin\AppData\Local\Programs\Python\Python312\Lib\contextlib.py", line 158, in __exit__
    self.gen.throw(value)
  File "C:\Users\Admin\AppData\Local\Programs\Python\Python312\Lib\site-packages\httpx\_transports\default.py", line 89, in map_httpcore_exceptions
    raise mapped_exc(message) from exc
httpx.ConnectError: [Errno 11001] getaddrinfo failed

The above exception was the direct cause of the following exception:

Traceback (most recent call last):
  File "C:\Users\Admin\AppData\Local\Programs\Python\Python312\Lib\site-packages\telegram\ext\_updater.py", line 750, in _network_loop_retry
    if not await do_action():
           ^^^^^^^^^^^^^^^^^
  File "C:\Users\Admin\AppData\Local\Programs\Python\Python312\Lib\site-packages\telegram\ext\_updater.py", line 744, in do_action
    return action_cb_task.result()
           ^^^^^^^^^^^^^^^^^^^^^^^
  File "C:\Users\Admin\AppData\Local\Programs\Python\Python312\Lib\asyncio\futures.py", line 203, in result
    raise self._exception.with_traceback(self._exception_tb)
  File "C:\Users\Admin\AppData\Local\Programs\Python\Python312\Lib\asyncio\tasks.py", line 316, in __step_run_and_handle_result
    result = coro.throw(exc)
             ^^^^^^^^^^^^^^^
  File "C:\Users\Admin\AppData\Local\Programs\Python\Python312\Lib\site-packages\telegram\ext\_updater.py", line 371, in polling_action_cb
    updates = await self.bot.get_updates(
              ^^^^^^^^^^^^^^^^^^^^^^^^^^^
  File "C:\Users\Admin\AppData\Local\Programs\Python\Python312\Lib\site-packages\telegram\ext\_extbot.py", line 650, in get_updates
    updates = await super().get_updates(
              ^^^^^^^^^^^^^^^^^^^^^^^^^^
  File "C:\Users\Admin\AppData\Local\Programs\Python\Python312\Lib\site-packages\telegram\_bot.py", line 4480, in get_updates
    await self._post(
  File "C:\Users\Admin\AppData\Local\Programs\Python\Python312\Lib\site-packages\telegram\_bot.py", line 619, in _post
    return await self._do_post(
           ^^^^^^^^^^^^^^^^^^^^
  File "C:\Users\Admin\AppData\Local\Programs\Python\Python312\Lib\site-packages\telegram\ext\_extbot.py", line 354, in _do_post
    return await super()._do_post(
           ^^^^^^^^^^^^^^^^^^^^^^^
  File "C:\Users\Admin\AppData\Local\Programs\Python\Python312\Lib\site-packages\telegram\_bot.py", line 648, in _do_post
    result = await request.post(
             ^^^^^^^^^^^^^^^^^^^
  File "C:\Users\Admin\AppData\Local\Programs\Python\Python312\Lib\site-packages\telegram\request\_baserequest.py", line 202, in post
    result = await self._request_wrapper(
             ^^^^^^^^^^^^^^^^^^^^^^^^^^^^
  File "C:\Users\Admin\AppData\Local\Programs\Python\Python312\Lib\site-packages\telegram\request\_baserequest.py", line 334, in _request_wrapper
    code, payload = await self.do_request(
                    ^^^^^^^^^^^^^^^^^^^^^^
  File "C:\Users\Admin\AppData\Local\Programs\Python\Python312\Lib\site-packages\telegram\request\_httpxrequest.py", line 317, in do_request
    raise NetworkError(f"httpx.{err.__class__.__name__}: {err}") from err
telegram.error.NetworkError: httpx.ConnectError: [Errno 11001] getaddrinfo failed
2024-12-21 15:47:39,739 - __main__ - INFO - База данных инициализирована.
2024-12-21 15:47:42,925 - __main__ - INFO - Обработчики добавлены. Бот запускается.
2024-12-21 15:48:21,610 - __main__ - INFO - База данных инициализирована.
2024-12-21 15:48:24,911 - __main__ - INFO - Обработчики добавлены. Бот запускается.
2024-12-21 15:54:35,044 - __main__ - INFO - База данных инициализирована.
2024-12-21 15:54:37,926 - __main__ - INFO - Обработчики добавлены. Бот запускается.
2024-12-21 15:54:45,284 - apscheduler.scheduler - INFO - Scheduler started
2024-12-21 15:54:45,320 - telegram.ext.Application - INFO - Application started
2024-12-21 15:54:46,164 - __main__ - INFO - Команда /info вызвана пользователем @shineSwa (1753361154).
2024-12-21 15:54:46,385 - __main__ - INFO - Команда /info вызвана пользователем @shineSwa (1753361154).
2024-12-21 15:54:46,564 - __main__ - INFO - Команда /list вызвана.
2024-12-21 15:54:46,768 - __main__ - INFO - Команда /info вызвана пользователем @shineSwa (1753361154).
2024-12-21 15:55:26,670 - __main__ - INFO - Команда /myrank вызвана пользователем 1753361154.
2024-12-21 15:57:05,094 - __main__ - INFO - Команда /list вызвана.
2024-12-21 15:57:10,081 - __main__ - INFO - Пользователь 1753361154 инициировал /start.
2024-12-21 15:57:16,445 - __main__ - INFO - Пользователь 1753361154 просмотрел профиль пользователя 2128746010.
2024-12-21 15:59:39,960 - __main__ - INFO - Пользователь 1753361154 просмотрел профиль пользователя 2128746010.
2024-12-21 15:59:41,410 - __main__ - INFO - Пользователь 2128746010 отправил сообщение пользователю @shineSwa (1753361154) анонимно=False.
2024-12-21 15:59:57,489 - __main__ - INFO - Пользователь 1753361154 просмотрел профиль пользователя 2128746010.
2024-12-21 16:00:55,658 - __main__ - INFO - Пользователь 2128746010 просмотрел профиль пользователя 1753361154.
2024-12-21 16:01:30,456 - __main__ - INFO - Пользователь 1753361154 отправил сообщение пользователю @Huapryanik (2128746010) анонимно=False.
2024-12-21 16:01:43,867 - __main__ - INFO - Пользователь 2128746010 ответил пользователю @shineSwa (1753361154) анонимно=False.
2024-12-21 16:01:47,519 - __main__ - INFO - Пользователь 2128746010 ответил пользователю @shineSwa (1753361154) анонимно=False.
2024-12-21 16:02:05,749 - __main__ - INFO - Пользователь 1753361154 ответил пользователю @Huapryanik (2128746010) анонимно=False.
2024-12-21 16:02:29,575 - __main__ - INFO - Пользователь 1753361154 ответил пользователю @Huapryanik (2128746010) анонимно=False.
2024-12-21 16:03:47,285 - __main__ - INFO - Пользователь 2128746010 ответил пользователю @shineSwa (1753361154) анонимно=False.
2024-12-21 16:04:04,878 - __main__ - INFO - Пользователь 1753361154 ответил пользователю @Huapryanik (2128746010) анонимно=False.
2024-12-21 16:04:06,880 - __main__ - INFO - Пользователь 2128746010 ответил пользователю @shineSwa (1753361154) анонимно=False.
2024-12-21 16:04:18,668 - __main__ - INFO - Пользователь 1753361154 ответил пользователю @Huapryanik (2128746010) анонимно=False.
2024-12-21 16:09:21,796 - __main__ - INFO - Пользователь 1196314708 установил фотографию профиля.
2024-12-21 16:09:34,638 - __main__ - INFO - Команда /help вызвана.
2024-12-21 16:10:06,735 - __main__ - INFO - Пользователь 1753361154 просмотрел профиль пользователя 2128746010.
2024-12-21 16:10:17,574 - __main__ - INFO - Пользователь 1196314708 инициировал /start.
2024-12-21 16:10:28,188 - __main__ - INFO - Пользователь 1196314708 зарегистрирован как @Syesonn.
2024-12-21 16:10:37,546 - __main__ - INFO - Пользователь 1753361154 отправил сообщение пользователю @Huapryanik (2128746010) анонимно=False.
2024-12-21 16:10:43,351 - __main__ - INFO - Пользователь @Syesonn (1196314708) обновил свои интересы: музыка, рисование, театр
2024-12-21 16:10:43,595 - __main__ - INFO - Пользователь 1753361154 просмотрел профиль пользователя 2128746010.
2024-12-21 16:10:45,926 - __main__ - INFO - Пользователь 1753361154 просмотрел профиль пользователя 1196314708.
2024-12-21 16:10:57,094 - __main__ - INFO - Пользователь 1196314708 установил фотографию профиля.
2024-12-21 16:11:05,203 - __main__ - INFO - Пользователь 1753361154 просмотрел профиль пользователя 1196314708.
2024-12-21 16:12:53,909 - __main__ - INFO - Команда /info вызвана пользователем @Syesonn (1196314708).
2024-12-21 16:16:49,948 - __main__ - INFO - Пользователь 1753361154 просмотрел профиль пользователя 1196314708.
2024-12-21 16:22:07,812 - __main__ - INFO - Команда /list вызвана.
2024-12-21 16:52:17,605 - __main__ - INFO - Пользователь 1753361154 отправил сообщение пользователю @Syesonn (1196314708) анонимно=False.
2024-12-21 16:53:01,935 - __main__ - INFO - Команда /list вызвана.
2024-12-21 16:59:12,120 - __main__ - INFO - Пользователь 1196314708 ответил пользователю @shineSwa (1753361154) анонимно=False.
2024-12-21 20:04:08,472 - __main__ - INFO - База данных инициализирована.
2024-12-21 20:04:11,739 - __main__ - INFO - Обработчики добавлены. Бот запускается.
2024-12-21 20:04:13,275 - apscheduler.scheduler - INFO - Scheduler started
2024-12-21 20:04:13,276 - telegram.ext.Application - INFO - Application started
2024-12-21 20:04:14,100 - __main__ - INFO - Команда /list вызвана.
2024-12-21 20:04:14,513 - __main__ - INFO - Команда /help вызвана.
2024-12-21 22:33:20,676 - __main__ - ERROR - Обнаружена ошибка:
Traceback (most recent call last):
  File "C:\Users\Admin\AppData\Local\Programs\Python\Python312\Lib\site-packages\httpx\_transports\default.py", line 72, in map_httpcore_exceptions
    yield
  File "C:\Users\Admin\AppData\Local\Programs\Python\Python312\Lib\site-packages\httpx\_transports\default.py", line 377, in handle_async_request
    resp = await self._pool.handle_async_request(req)
           ^^^^^^^^^^^^^^^^^^^^^^^^^^^^^^^^^^^^^^^^^^
  File "C:\Users\Admin\AppData\Local\Programs\Python\Python312\Lib\site-packages\httpcore\_async\connection_pool.py", line 216, in handle_async_request
    raise exc from None
  File "C:\Users\Admin\AppData\Local\Programs\Python\Python312\Lib\site-packages\httpcore\_async\connection_pool.py", line 196, in handle_async_request
    response = await connection.handle_async_request(
               ^^^^^^^^^^^^^^^^^^^^^^^^^^^^^^^^^^^^^^
  File "C:\Users\Admin\AppData\Local\Programs\Python\Python312\Lib\site-packages\httpcore\_async\connection.py", line 99, in handle_async_request
    raise exc
  File "C:\Users\Admin\AppData\Local\Programs\Python\Python312\Lib\site-packages\httpcore\_async\connection.py", line 76, in handle_async_request
    stream = await self._connect(request)
             ^^^^^^^^^^^^^^^^^^^^^^^^^^^^
  File "C:\Users\Admin\AppData\Local\Programs\Python\Python312\Lib\site-packages\httpcore\_async\connection.py", line 122, in _connect
    stream = await self._network_backend.connect_tcp(**kwargs)
             ^^^^^^^^^^^^^^^^^^^^^^^^^^^^^^^^^^^^^^^^^^^^^^^^^
  File "C:\Users\Admin\AppData\Local\Programs\Python\Python312\Lib\site-packages\httpcore\_backends\auto.py", line 30, in connect_tcp
    return await self._backend.connect_tcp(
           ^^^^^^^^^^^^^^^^^^^^^^^^^^^^^^^^
  File "C:\Users\Admin\AppData\Local\Programs\Python\Python312\Lib\site-packages\httpcore\_backends\anyio.py", line 115, in connect_tcp
    with map_exceptions(exc_map):
  File "C:\Users\Admin\AppData\Local\Programs\Python\Python312\Lib\contextlib.py", line 158, in __exit__
    self.gen.throw(value)
  File "C:\Users\Admin\AppData\Local\Programs\Python\Python312\Lib\site-packages\httpcore\_exceptions.py", line 14, in map_exceptions
    raise to_exc(exc) from exc
httpcore.ConnectError: [Errno 11001] getaddrinfo failed

The above exception was the direct cause of the following exception:

Traceback (most recent call last):
  File "C:\Users\Admin\AppData\Local\Programs\Python\Python312\Lib\site-packages\telegram\request\_httpxrequest.py", line 293, in do_request
    res = await self._client.request(
          ^^^^^^^^^^^^^^^^^^^^^^^^^^^
  File "C:\Users\Admin\AppData\Local\Programs\Python\Python312\Lib\site-packages\httpx\_client.py", line 1585, in request
    return await self.send(request, auth=auth, follow_redirects=follow_redirects)
           ^^^^^^^^^^^^^^^^^^^^^^^^^^^^^^^^^^^^^^^^^^^^^^^^^^^^^^^^^^^^^^^^^^^^^^
  File "C:\Users\Admin\AppData\Local\Programs\Python\Python312\Lib\site-packages\httpx\_client.py", line 1674, in send
    response = await self._send_handling_auth(
               ^^^^^^^^^^^^^^^^^^^^^^^^^^^^^^^
  File "C:\Users\Admin\AppData\Local\Programs\Python\Python312\Lib\site-packages\httpx\_client.py", line 1702, in _send_handling_auth
    response = await self._send_handling_redirects(
               ^^^^^^^^^^^^^^^^^^^^^^^^^^^^^^^^^^^^
  File "C:\Users\Admin\AppData\Local\Programs\Python\Python312\Lib\site-packages\httpx\_client.py", line 1739, in _send_handling_redirects
    response = await self._send_single_request(request)
               ^^^^^^^^^^^^^^^^^^^^^^^^^^^^^^^^^^^^^^^^
  File "C:\Users\Admin\AppData\Local\Programs\Python\Python312\Lib\site-packages\httpx\_client.py", line 1776, in _send_single_request
    response = await transport.handle_async_request(request)
               ^^^^^^^^^^^^^^^^^^^^^^^^^^^^^^^^^^^^^^^^^^^^^
  File "C:\Users\Admin\AppData\Local\Programs\Python\Python312\Lib\site-packages\httpx\_transports\default.py", line 376, in handle_async_request
    with map_httpcore_exceptions():
  File "C:\Users\Admin\AppData\Local\Programs\Python\Python312\Lib\contextlib.py", line 158, in __exit__
    self.gen.throw(value)
  File "C:\Users\Admin\AppData\Local\Programs\Python\Python312\Lib\site-packages\httpx\_transports\default.py", line 89, in map_httpcore_exceptions
    raise mapped_exc(message) from exc
httpx.ConnectError: [Errno 11001] getaddrinfo failed

The above exception was the direct cause of the following exception:

Traceback (most recent call last):
  File "C:\Users\Admin\AppData\Local\Programs\Python\Python312\Lib\site-packages\telegram\ext\_updater.py", line 750, in _network_loop_retry
    if not await do_action():
           ^^^^^^^^^^^^^^^^^
  File "C:\Users\Admin\AppData\Local\Programs\Python\Python312\Lib\site-packages\telegram\ext\_updater.py", line 744, in do_action
    return action_cb_task.result()
           ^^^^^^^^^^^^^^^^^^^^^^^
  File "C:\Users\Admin\AppData\Local\Programs\Python\Python312\Lib\asyncio\futures.py", line 203, in result
    raise self._exception.with_traceback(self._exception_tb)
  File "C:\Users\Admin\AppData\Local\Programs\Python\Python312\Lib\asyncio\tasks.py", line 316, in __step_run_and_handle_result
    result = coro.throw(exc)
             ^^^^^^^^^^^^^^^
  File "C:\Users\Admin\AppData\Local\Programs\Python\Python312\Lib\site-packages\telegram\ext\_updater.py", line 371, in polling_action_cb
    updates = await self.bot.get_updates(
              ^^^^^^^^^^^^^^^^^^^^^^^^^^^
  File "C:\Users\Admin\AppData\Local\Programs\Python\Python312\Lib\site-packages\telegram\ext\_extbot.py", line 650, in get_updates
    updates = await super().get_updates(
              ^^^^^^^^^^^^^^^^^^^^^^^^^^
  File "C:\Users\Admin\AppData\Local\Programs\Python\Python312\Lib\site-packages\telegram\_bot.py", line 4480, in get_updates
    await self._post(
  File "C:\Users\Admin\AppData\Local\Programs\Python\Python312\Lib\site-packages\telegram\_bot.py", line 619, in _post
    return await self._do_post(
           ^^^^^^^^^^^^^^^^^^^^
  File "C:\Users\Admin\AppData\Local\Programs\Python\Python312\Lib\site-packages\telegram\ext\_extbot.py", line 354, in _do_post
    return await super()._do_post(
           ^^^^^^^^^^^^^^^^^^^^^^^
  File "C:\Users\Admin\AppData\Local\Programs\Python\Python312\Lib\site-packages\telegram\_bot.py", line 648, in _do_post
    result = await request.post(
             ^^^^^^^^^^^^^^^^^^^
  File "C:\Users\Admin\AppData\Local\Programs\Python\Python312\Lib\site-packages\telegram\request\_baserequest.py", line 202, in post
    result = await self._request_wrapper(
             ^^^^^^^^^^^^^^^^^^^^^^^^^^^^
  File "C:\Users\Admin\AppData\Local\Programs\Python\Python312\Lib\site-packages\telegram\request\_baserequest.py", line 334, in _request_wrapper
    code, payload = await self.do_request(
                    ^^^^^^^^^^^^^^^^^^^^^^
  File "C:\Users\Admin\AppData\Local\Programs\Python\Python312\Lib\site-packages\telegram\request\_httpxrequest.py", line 317, in do_request
    raise NetworkError(f"httpx.{err.__class__.__name__}: {err}") from err
telegram.error.NetworkError: httpx.ConnectError: [Errno 11001] getaddrinfo failed
2024-12-21 22:33:21,629 - __main__ - ERROR - Обнаружена ошибка:
Traceback (most recent call last):
  File "C:\Users\Admin\AppData\Local\Programs\Python\Python312\Lib\site-packages\httpx\_transports\default.py", line 72, in map_httpcore_exceptions
    yield
  File "C:\Users\Admin\AppData\Local\Programs\Python\Python312\Lib\site-packages\httpx\_transports\default.py", line 377, in handle_async_request
    resp = await self._pool.handle_async_request(req)
           ^^^^^^^^^^^^^^^^^^^^^^^^^^^^^^^^^^^^^^^^^^
  File "C:\Users\Admin\AppData\Local\Programs\Python\Python312\Lib\site-packages\httpcore\_async\connection_pool.py", line 216, in handle_async_request
    raise exc from None
  File "C:\Users\Admin\AppData\Local\Programs\Python\Python312\Lib\site-packages\httpcore\_async\connection_pool.py", line 196, in handle_async_request
    response = await connection.handle_async_request(
               ^^^^^^^^^^^^^^^^^^^^^^^^^^^^^^^^^^^^^^
  File "C:\Users\Admin\AppData\Local\Programs\Python\Python312\Lib\site-packages\httpcore\_async\connection.py", line 99, in handle_async_request
    raise exc
  File "C:\Users\Admin\AppData\Local\Programs\Python\Python312\Lib\site-packages\httpcore\_async\connection.py", line 76, in handle_async_request
    stream = await self._connect(request)
             ^^^^^^^^^^^^^^^^^^^^^^^^^^^^
  File "C:\Users\Admin\AppData\Local\Programs\Python\Python312\Lib\site-packages\httpcore\_async\connection.py", line 122, in _connect
    stream = await self._network_backend.connect_tcp(**kwargs)
             ^^^^^^^^^^^^^^^^^^^^^^^^^^^^^^^^^^^^^^^^^^^^^^^^^
  File "C:\Users\Admin\AppData\Local\Programs\Python\Python312\Lib\site-packages\httpcore\_backends\auto.py", line 30, in connect_tcp
    return await self._backend.connect_tcp(
           ^^^^^^^^^^^^^^^^^^^^^^^^^^^^^^^^
  File "C:\Users\Admin\AppData\Local\Programs\Python\Python312\Lib\site-packages\httpcore\_backends\anyio.py", line 115, in connect_tcp
    with map_exceptions(exc_map):
  File "C:\Users\Admin\AppData\Local\Programs\Python\Python312\Lib\contextlib.py", line 158, in __exit__
    self.gen.throw(value)
  File "C:\Users\Admin\AppData\Local\Programs\Python\Python312\Lib\site-packages\httpcore\_exceptions.py", line 14, in map_exceptions
    raise to_exc(exc) from exc
httpcore.ConnectError: [Errno 11001] getaddrinfo failed

The above exception was the direct cause of the following exception:

Traceback (most recent call last):
  File "C:\Users\Admin\AppData\Local\Programs\Python\Python312\Lib\site-packages\telegram\request\_httpxrequest.py", line 293, in do_request
    res = await self._client.request(
          ^^^^^^^^^^^^^^^^^^^^^^^^^^^
  File "C:\Users\Admin\AppData\Local\Programs\Python\Python312\Lib\site-packages\httpx\_client.py", line 1585, in request
    return await self.send(request, auth=auth, follow_redirects=follow_redirects)
           ^^^^^^^^^^^^^^^^^^^^^^^^^^^^^^^^^^^^^^^^^^^^^^^^^^^^^^^^^^^^^^^^^^^^^^
  File "C:\Users\Admin\AppData\Local\Programs\Python\Python312\Lib\site-packages\httpx\_client.py", line 1674, in send
    response = await self._send_handling_auth(
               ^^^^^^^^^^^^^^^^^^^^^^^^^^^^^^^
  File "C:\Users\Admin\AppData\Local\Programs\Python\Python312\Lib\site-packages\httpx\_client.py", line 1702, in _send_handling_auth
    response = await self._send_handling_redirects(
               ^^^^^^^^^^^^^^^^^^^^^^^^^^^^^^^^^^^^
  File "C:\Users\Admin\AppData\Local\Programs\Python\Python312\Lib\site-packages\httpx\_client.py", line 1739, in _send_handling_redirects
    response = await self._send_single_request(request)
               ^^^^^^^^^^^^^^^^^^^^^^^^^^^^^^^^^^^^^^^^
  File "C:\Users\Admin\AppData\Local\Programs\Python\Python312\Lib\site-packages\httpx\_client.py", line 1776, in _send_single_request
    response = await transport.handle_async_request(request)
               ^^^^^^^^^^^^^^^^^^^^^^^^^^^^^^^^^^^^^^^^^^^^^
  File "C:\Users\Admin\AppData\Local\Programs\Python\Python312\Lib\site-packages\httpx\_transports\default.py", line 376, in handle_async_request
    with map_httpcore_exceptions():
  File "C:\Users\Admin\AppData\Local\Programs\Python\Python312\Lib\contextlib.py", line 158, in __exit__
    self.gen.throw(value)
  File "C:\Users\Admin\AppData\Local\Programs\Python\Python312\Lib\site-packages\httpx\_transports\default.py", line 89, in map_httpcore_exceptions
    raise mapped_exc(message) from exc
httpx.ConnectError: [Errno 11001] getaddrinfo failed

The above exception was the direct cause of the following exception:

Traceback (most recent call last):
  File "C:\Users\Admin\AppData\Local\Programs\Python\Python312\Lib\site-packages\telegram\ext\_updater.py", line 750, in _network_loop_retry
    if not await do_action():
           ^^^^^^^^^^^^^^^^^
  File "C:\Users\Admin\AppData\Local\Programs\Python\Python312\Lib\site-packages\telegram\ext\_updater.py", line 744, in do_action
    return action_cb_task.result()
           ^^^^^^^^^^^^^^^^^^^^^^^
  File "C:\Users\Admin\AppData\Local\Programs\Python\Python312\Lib\asyncio\futures.py", line 203, in result
    raise self._exception.with_traceback(self._exception_tb)
  File "C:\Users\Admin\AppData\Local\Programs\Python\Python312\Lib\asyncio\tasks.py", line 316, in __step_run_and_handle_result
    result = coro.throw(exc)
             ^^^^^^^^^^^^^^^
  File "C:\Users\Admin\AppData\Local\Programs\Python\Python312\Lib\site-packages\telegram\ext\_updater.py", line 371, in polling_action_cb
    updates = await self.bot.get_updates(
              ^^^^^^^^^^^^^^^^^^^^^^^^^^^
  File "C:\Users\Admin\AppData\Local\Programs\Python\Python312\Lib\site-packages\telegram\ext\_extbot.py", line 650, in get_updates
    updates = await super().get_updates(
              ^^^^^^^^^^^^^^^^^^^^^^^^^^
  File "C:\Users\Admin\AppData\Local\Programs\Python\Python312\Lib\site-packages\telegram\_bot.py", line 4480, in get_updates
    await self._post(
  File "C:\Users\Admin\AppData\Local\Programs\Python\Python312\Lib\site-packages\telegram\_bot.py", line 619, in _post
    return await self._do_post(
           ^^^^^^^^^^^^^^^^^^^^
  File "C:\Users\Admin\AppData\Local\Programs\Python\Python312\Lib\site-packages\telegram\ext\_extbot.py", line 354, in _do_post
    return await super()._do_post(
           ^^^^^^^^^^^^^^^^^^^^^^^
  File "C:\Users\Admin\AppData\Local\Programs\Python\Python312\Lib\site-packages\telegram\_bot.py", line 648, in _do_post
    result = await request.post(
             ^^^^^^^^^^^^^^^^^^^
  File "C:\Users\Admin\AppData\Local\Programs\Python\Python312\Lib\site-packages\telegram\request\_baserequest.py", line 202, in post
    result = await self._request_wrapper(
             ^^^^^^^^^^^^^^^^^^^^^^^^^^^^
  File "C:\Users\Admin\AppData\Local\Programs\Python\Python312\Lib\site-packages\telegram\request\_baserequest.py", line 334, in _request_wrapper
    code, payload = await self.do_request(
                    ^^^^^^^^^^^^^^^^^^^^^^
  File "C:\Users\Admin\AppData\Local\Programs\Python\Python312\Lib\site-packages\telegram\request\_httpxrequest.py", line 317, in do_request
    raise NetworkError(f"httpx.{err.__class__.__name__}: {err}") from err
telegram.error.NetworkError: httpx.ConnectError: [Errno 11001] getaddrinfo failed
2024-12-21 22:33:23,133 - __main__ - ERROR - Обнаружена ошибка:
Traceback (most recent call last):
  File "C:\Users\Admin\AppData\Local\Programs\Python\Python312\Lib\site-packages\httpx\_transports\default.py", line 72, in map_httpcore_exceptions
    yield
  File "C:\Users\Admin\AppData\Local\Programs\Python\Python312\Lib\site-packages\httpx\_transports\default.py", line 377, in handle_async_request
    resp = await self._pool.handle_async_request(req)
           ^^^^^^^^^^^^^^^^^^^^^^^^^^^^^^^^^^^^^^^^^^
  File "C:\Users\Admin\AppData\Local\Programs\Python\Python312\Lib\site-packages\httpcore\_async\connection_pool.py", line 216, in handle_async_request
    raise exc from None
  File "C:\Users\Admin\AppData\Local\Programs\Python\Python312\Lib\site-packages\httpcore\_async\connection_pool.py", line 196, in handle_async_request
    response = await connection.handle_async_request(
               ^^^^^^^^^^^^^^^^^^^^^^^^^^^^^^^^^^^^^^
  File "C:\Users\Admin\AppData\Local\Programs\Python\Python312\Lib\site-packages\httpcore\_async\connection.py", line 99, in handle_async_request
    raise exc
  File "C:\Users\Admin\AppData\Local\Programs\Python\Python312\Lib\site-packages\httpcore\_async\connection.py", line 76, in handle_async_request
    stream = await self._connect(request)
             ^^^^^^^^^^^^^^^^^^^^^^^^^^^^
  File "C:\Users\Admin\AppData\Local\Programs\Python\Python312\Lib\site-packages\httpcore\_async\connection.py", line 122, in _connect
    stream = await self._network_backend.connect_tcp(**kwargs)
             ^^^^^^^^^^^^^^^^^^^^^^^^^^^^^^^^^^^^^^^^^^^^^^^^^
  File "C:\Users\Admin\AppData\Local\Programs\Python\Python312\Lib\site-packages\httpcore\_backends\auto.py", line 30, in connect_tcp
    return await self._backend.connect_tcp(
           ^^^^^^^^^^^^^^^^^^^^^^^^^^^^^^^^
  File "C:\Users\Admin\AppData\Local\Programs\Python\Python312\Lib\site-packages\httpcore\_backends\anyio.py", line 115, in connect_tcp
    with map_exceptions(exc_map):
  File "C:\Users\Admin\AppData\Local\Programs\Python\Python312\Lib\contextlib.py", line 158, in __exit__
    self.gen.throw(value)
  File "C:\Users\Admin\AppData\Local\Programs\Python\Python312\Lib\site-packages\httpcore\_exceptions.py", line 14, in map_exceptions
    raise to_exc(exc) from exc
httpcore.ConnectError: [Errno 11001] getaddrinfo failed

The above exception was the direct cause of the following exception:

Traceback (most recent call last):
  File "C:\Users\Admin\AppData\Local\Programs\Python\Python312\Lib\site-packages\telegram\request\_httpxrequest.py", line 293, in do_request
    res = await self._client.request(
          ^^^^^^^^^^^^^^^^^^^^^^^^^^^
  File "C:\Users\Admin\AppData\Local\Programs\Python\Python312\Lib\site-packages\httpx\_client.py", line 1585, in request
    return await self.send(request, auth=auth, follow_redirects=follow_redirects)
           ^^^^^^^^^^^^^^^^^^^^^^^^^^^^^^^^^^^^^^^^^^^^^^^^^^^^^^^^^^^^^^^^^^^^^^
  File "C:\Users\Admin\AppData\Local\Programs\Python\Python312\Lib\site-packages\httpx\_client.py", line 1674, in send
    response = await self._send_handling_auth(
               ^^^^^^^^^^^^^^^^^^^^^^^^^^^^^^^
  File "C:\Users\Admin\AppData\Local\Programs\Python\Python312\Lib\site-packages\httpx\_client.py", line 1702, in _send_handling_auth
    response = await self._send_handling_redirects(
               ^^^^^^^^^^^^^^^^^^^^^^^^^^^^^^^^^^^^
  File "C:\Users\Admin\AppData\Local\Programs\Python\Python312\Lib\site-packages\httpx\_client.py", line 1739, in _send_handling_redirects
    response = await self._send_single_request(request)
               ^^^^^^^^^^^^^^^^^^^^^^^^^^^^^^^^^^^^^^^^
  File "C:\Users\Admin\AppData\Local\Programs\Python\Python312\Lib\site-packages\httpx\_client.py", line 1776, in _send_single_request
    response = await transport.handle_async_request(request)
               ^^^^^^^^^^^^^^^^^^^^^^^^^^^^^^^^^^^^^^^^^^^^^
  File "C:\Users\Admin\AppData\Local\Programs\Python\Python312\Lib\site-packages\httpx\_transports\default.py", line 376, in handle_async_request
    with map_httpcore_exceptions():
  File "C:\Users\Admin\AppData\Local\Programs\Python\Python312\Lib\contextlib.py", line 158, in __exit__
    self.gen.throw(value)
  File "C:\Users\Admin\AppData\Local\Programs\Python\Python312\Lib\site-packages\httpx\_transports\default.py", line 89, in map_httpcore_exceptions
    raise mapped_exc(message) from exc
httpx.ConnectError: [Errno 11001] getaddrinfo failed

The above exception was the direct cause of the following exception:

Traceback (most recent call last):
  File "C:\Users\Admin\AppData\Local\Programs\Python\Python312\Lib\site-packages\telegram\ext\_updater.py", line 750, in _network_loop_retry
    if not await do_action():
           ^^^^^^^^^^^^^^^^^
  File "C:\Users\Admin\AppData\Local\Programs\Python\Python312\Lib\site-packages\telegram\ext\_updater.py", line 744, in do_action
    return action_cb_task.result()
           ^^^^^^^^^^^^^^^^^^^^^^^
  File "C:\Users\Admin\AppData\Local\Programs\Python\Python312\Lib\asyncio\futures.py", line 203, in result
    raise self._exception.with_traceback(self._exception_tb)
  File "C:\Users\Admin\AppData\Local\Programs\Python\Python312\Lib\asyncio\tasks.py", line 316, in __step_run_and_handle_result
    result = coro.throw(exc)
             ^^^^^^^^^^^^^^^
  File "C:\Users\Admin\AppData\Local\Programs\Python\Python312\Lib\site-packages\telegram\ext\_updater.py", line 371, in polling_action_cb
    updates = await self.bot.get_updates(
              ^^^^^^^^^^^^^^^^^^^^^^^^^^^
  File "C:\Users\Admin\AppData\Local\Programs\Python\Python312\Lib\site-packages\telegram\ext\_extbot.py", line 650, in get_updates
    updates = await super().get_updates(
              ^^^^^^^^^^^^^^^^^^^^^^^^^^
  File "C:\Users\Admin\AppData\Local\Programs\Python\Python312\Lib\site-packages\telegram\_bot.py", line 4480, in get_updates
    await self._post(
  File "C:\Users\Admin\AppData\Local\Programs\Python\Python312\Lib\site-packages\telegram\_bot.py", line 619, in _post
    return await self._do_post(
           ^^^^^^^^^^^^^^^^^^^^
  File "C:\Users\Admin\AppData\Local\Programs\Python\Python312\Lib\site-packages\telegram\ext\_extbot.py", line 354, in _do_post
    return await super()._do_post(
           ^^^^^^^^^^^^^^^^^^^^^^^
  File "C:\Users\Admin\AppData\Local\Programs\Python\Python312\Lib\site-packages\telegram\_bot.py", line 648, in _do_post
    result = await request.post(
             ^^^^^^^^^^^^^^^^^^^
  File "C:\Users\Admin\AppData\Local\Programs\Python\Python312\Lib\site-packages\telegram\request\_baserequest.py", line 202, in post
    result = await self._request_wrapper(
             ^^^^^^^^^^^^^^^^^^^^^^^^^^^^
  File "C:\Users\Admin\AppData\Local\Programs\Python\Python312\Lib\site-packages\telegram\request\_baserequest.py", line 334, in _request_wrapper
    code, payload = await self.do_request(
                    ^^^^^^^^^^^^^^^^^^^^^^
  File "C:\Users\Admin\AppData\Local\Programs\Python\Python312\Lib\site-packages\telegram\request\_httpxrequest.py", line 317, in do_request
    raise NetworkError(f"httpx.{err.__class__.__name__}: {err}") from err
telegram.error.NetworkError: httpx.ConnectError: [Errno 11001] getaddrinfo failed
2024-12-21 22:38:01,653 - __main__ - ERROR - Обнаружена ошибка:
Traceback (most recent call last):
  File "C:\Users\Admin\AppData\Local\Programs\Python\Python312\Lib\site-packages\httpx\_transports\default.py", line 72, in map_httpcore_exceptions
    yield
  File "C:\Users\Admin\AppData\Local\Programs\Python\Python312\Lib\site-packages\httpx\_transports\default.py", line 377, in handle_async_request
    resp = await self._pool.handle_async_request(req)
           ^^^^^^^^^^^^^^^^^^^^^^^^^^^^^^^^^^^^^^^^^^
  File "C:\Users\Admin\AppData\Local\Programs\Python\Python312\Lib\site-packages\httpcore\_async\connection_pool.py", line 216, in handle_async_request
    raise exc from None
  File "C:\Users\Admin\AppData\Local\Programs\Python\Python312\Lib\site-packages\httpcore\_async\connection_pool.py", line 196, in handle_async_request
    response = await connection.handle_async_request(
               ^^^^^^^^^^^^^^^^^^^^^^^^^^^^^^^^^^^^^^
  File "C:\Users\Admin\AppData\Local\Programs\Python\Python312\Lib\site-packages\httpcore\_async\connection.py", line 99, in handle_async_request
    raise exc
  File "C:\Users\Admin\AppData\Local\Programs\Python\Python312\Lib\site-packages\httpcore\_async\connection.py", line 76, in handle_async_request
    stream = await self._connect(request)
             ^^^^^^^^^^^^^^^^^^^^^^^^^^^^
  File "C:\Users\Admin\AppData\Local\Programs\Python\Python312\Lib\site-packages\httpcore\_async\connection.py", line 122, in _connect
    stream = await self._network_backend.connect_tcp(**kwargs)
             ^^^^^^^^^^^^^^^^^^^^^^^^^^^^^^^^^^^^^^^^^^^^^^^^^
  File "C:\Users\Admin\AppData\Local\Programs\Python\Python312\Lib\site-packages\httpcore\_backends\auto.py", line 30, in connect_tcp
    return await self._backend.connect_tcp(
           ^^^^^^^^^^^^^^^^^^^^^^^^^^^^^^^^
  File "C:\Users\Admin\AppData\Local\Programs\Python\Python312\Lib\site-packages\httpcore\_backends\anyio.py", line 115, in connect_tcp
    with map_exceptions(exc_map):
  File "C:\Users\Admin\AppData\Local\Programs\Python\Python312\Lib\contextlib.py", line 158, in __exit__
    self.gen.throw(value)
  File "C:\Users\Admin\AppData\Local\Programs\Python\Python312\Lib\site-packages\httpcore\_exceptions.py", line 14, in map_exceptions
    raise to_exc(exc) from exc
httpcore.ConnectError: [Errno 11001] getaddrinfo failed

The above exception was the direct cause of the following exception:

Traceback (most recent call last):
  File "C:\Users\Admin\AppData\Local\Programs\Python\Python312\Lib\site-packages\telegram\request\_httpxrequest.py", line 293, in do_request
    res = await self._client.request(
          ^^^^^^^^^^^^^^^^^^^^^^^^^^^
  File "C:\Users\Admin\AppData\Local\Programs\Python\Python312\Lib\site-packages\httpx\_client.py", line 1585, in request
    return await self.send(request, auth=auth, follow_redirects=follow_redirects)
           ^^^^^^^^^^^^^^^^^^^^^^^^^^^^^^^^^^^^^^^^^^^^^^^^^^^^^^^^^^^^^^^^^^^^^^
  File "C:\Users\Admin\AppData\Local\Programs\Python\Python312\Lib\site-packages\httpx\_client.py", line 1674, in send
    response = await self._send_handling_auth(
               ^^^^^^^^^^^^^^^^^^^^^^^^^^^^^^^
  File "C:\Users\Admin\AppData\Local\Programs\Python\Python312\Lib\site-packages\httpx\_client.py", line 1702, in _send_handling_auth
    response = await self._send_handling_redirects(
               ^^^^^^^^^^^^^^^^^^^^^^^^^^^^^^^^^^^^
  File "C:\Users\Admin\AppData\Local\Programs\Python\Python312\Lib\site-packages\httpx\_client.py", line 1739, in _send_handling_redirects
    response = await self._send_single_request(request)
               ^^^^^^^^^^^^^^^^^^^^^^^^^^^^^^^^^^^^^^^^
  File "C:\Users\Admin\AppData\Local\Programs\Python\Python312\Lib\site-packages\httpx\_client.py", line 1776, in _send_single_request
    response = await transport.handle_async_request(request)
               ^^^^^^^^^^^^^^^^^^^^^^^^^^^^^^^^^^^^^^^^^^^^^
  File "C:\Users\Admin\AppData\Local\Programs\Python\Python312\Lib\site-packages\httpx\_transports\default.py", line 376, in handle_async_request
    with map_httpcore_exceptions():
  File "C:\Users\Admin\AppData\Local\Programs\Python\Python312\Lib\contextlib.py", line 158, in __exit__
    self.gen.throw(value)
  File "C:\Users\Admin\AppData\Local\Programs\Python\Python312\Lib\site-packages\httpx\_transports\default.py", line 89, in map_httpcore_exceptions
    raise mapped_exc(message) from exc
httpx.ConnectError: [Errno 11001] getaddrinfo failed

The above exception was the direct cause of the following exception:

Traceback (most recent call last):
  File "C:\Users\Admin\AppData\Local\Programs\Python\Python312\Lib\site-packages\telegram\ext\_updater.py", line 750, in _network_loop_retry
    if not await do_action():
           ^^^^^^^^^^^^^^^^^
  File "C:\Users\Admin\AppData\Local\Programs\Python\Python312\Lib\site-packages\telegram\ext\_updater.py", line 744, in do_action
    return action_cb_task.result()
           ^^^^^^^^^^^^^^^^^^^^^^^
  File "C:\Users\Admin\AppData\Local\Programs\Python\Python312\Lib\asyncio\futures.py", line 203, in result
    raise self._exception.with_traceback(self._exception_tb)
  File "C:\Users\Admin\AppData\Local\Programs\Python\Python312\Lib\asyncio\tasks.py", line 316, in __step_run_and_handle_result
    result = coro.throw(exc)
             ^^^^^^^^^^^^^^^
  File "C:\Users\Admin\AppData\Local\Programs\Python\Python312\Lib\site-packages\telegram\ext\_updater.py", line 371, in polling_action_cb
    updates = await self.bot.get_updates(
              ^^^^^^^^^^^^^^^^^^^^^^^^^^^
  File "C:\Users\Admin\AppData\Local\Programs\Python\Python312\Lib\site-packages\telegram\ext\_extbot.py", line 650, in get_updates
    updates = await super().get_updates(
              ^^^^^^^^^^^^^^^^^^^^^^^^^^
  File "C:\Users\Admin\AppData\Local\Programs\Python\Python312\Lib\site-packages\telegram\_bot.py", line 4480, in get_updates
    await self._post(
  File "C:\Users\Admin\AppData\Local\Programs\Python\Python312\Lib\site-packages\telegram\_bot.py", line 619, in _post
    return await self._do_post(
           ^^^^^^^^^^^^^^^^^^^^
  File "C:\Users\Admin\AppData\Local\Programs\Python\Python312\Lib\site-packages\telegram\ext\_extbot.py", line 354, in _do_post
    return await super()._do_post(
           ^^^^^^^^^^^^^^^^^^^^^^^
  File "C:\Users\Admin\AppData\Local\Programs\Python\Python312\Lib\site-packages\telegram\_bot.py", line 648, in _do_post
    result = await request.post(
             ^^^^^^^^^^^^^^^^^^^
  File "C:\Users\Admin\AppData\Local\Programs\Python\Python312\Lib\site-packages\telegram\request\_baserequest.py", line 202, in post
    result = await self._request_wrapper(
             ^^^^^^^^^^^^^^^^^^^^^^^^^^^^
  File "C:\Users\Admin\AppData\Local\Programs\Python\Python312\Lib\site-packages\telegram\request\_baserequest.py", line 334, in _request_wrapper
    code, payload = await self.do_request(
                    ^^^^^^^^^^^^^^^^^^^^^^
  File "C:\Users\Admin\AppData\Local\Programs\Python\Python312\Lib\site-packages\telegram\request\_httpxrequest.py", line 317, in do_request
    raise NetworkError(f"httpx.{err.__class__.__name__}: {err}") from err
telegram.error.NetworkError: httpx.ConnectError: [Errno 11001] getaddrinfo failed
2024-12-21 22:38:02,730 - __main__ - ERROR - Обнаружена ошибка:
Traceback (most recent call last):
  File "C:\Users\Admin\AppData\Local\Programs\Python\Python312\Lib\site-packages\httpx\_transports\default.py", line 72, in map_httpcore_exceptions
    yield
  File "C:\Users\Admin\AppData\Local\Programs\Python\Python312\Lib\site-packages\httpx\_transports\default.py", line 377, in handle_async_request
    resp = await self._pool.handle_async_request(req)
           ^^^^^^^^^^^^^^^^^^^^^^^^^^^^^^^^^^^^^^^^^^
  File "C:\Users\Admin\AppData\Local\Programs\Python\Python312\Lib\site-packages\httpcore\_async\connection_pool.py", line 216, in handle_async_request
    raise exc from None
  File "C:\Users\Admin\AppData\Local\Programs\Python\Python312\Lib\site-packages\httpcore\_async\connection_pool.py", line 196, in handle_async_request
    response = await connection.handle_async_request(
               ^^^^^^^^^^^^^^^^^^^^^^^^^^^^^^^^^^^^^^
  File "C:\Users\Admin\AppData\Local\Programs\Python\Python312\Lib\site-packages\httpcore\_async\connection.py", line 99, in handle_async_request
    raise exc
  File "C:\Users\Admin\AppData\Local\Programs\Python\Python312\Lib\site-packages\httpcore\_async\connection.py", line 76, in handle_async_request
    stream = await self._connect(request)
             ^^^^^^^^^^^^^^^^^^^^^^^^^^^^
  File "C:\Users\Admin\AppData\Local\Programs\Python\Python312\Lib\site-packages\httpcore\_async\connection.py", line 122, in _connect
    stream = await self._network_backend.connect_tcp(**kwargs)
             ^^^^^^^^^^^^^^^^^^^^^^^^^^^^^^^^^^^^^^^^^^^^^^^^^
  File "C:\Users\Admin\AppData\Local\Programs\Python\Python312\Lib\site-packages\httpcore\_backends\auto.py", line 30, in connect_tcp
    return await self._backend.connect_tcp(
           ^^^^^^^^^^^^^^^^^^^^^^^^^^^^^^^^
  File "C:\Users\Admin\AppData\Local\Programs\Python\Python312\Lib\site-packages\httpcore\_backends\anyio.py", line 115, in connect_tcp
    with map_exceptions(exc_map):
  File "C:\Users\Admin\AppData\Local\Programs\Python\Python312\Lib\contextlib.py", line 158, in __exit__
    self.gen.throw(value)
  File "C:\Users\Admin\AppData\Local\Programs\Python\Python312\Lib\site-packages\httpcore\_exceptions.py", line 14, in map_exceptions
    raise to_exc(exc) from exc
httpcore.ConnectError: [Errno 11001] getaddrinfo failed

The above exception was the direct cause of the following exception:

Traceback (most recent call last):
  File "C:\Users\Admin\AppData\Local\Programs\Python\Python312\Lib\site-packages\telegram\request\_httpxrequest.py", line 293, in do_request
    res = await self._client.request(
          ^^^^^^^^^^^^^^^^^^^^^^^^^^^
  File "C:\Users\Admin\AppData\Local\Programs\Python\Python312\Lib\site-packages\httpx\_client.py", line 1585, in request
    return await self.send(request, auth=auth, follow_redirects=follow_redirects)
           ^^^^^^^^^^^^^^^^^^^^^^^^^^^^^^^^^^^^^^^^^^^^^^^^^^^^^^^^^^^^^^^^^^^^^^
  File "C:\Users\Admin\AppData\Local\Programs\Python\Python312\Lib\site-packages\httpx\_client.py", line 1674, in send
    response = await self._send_handling_auth(
               ^^^^^^^^^^^^^^^^^^^^^^^^^^^^^^^
  File "C:\Users\Admin\AppData\Local\Programs\Python\Python312\Lib\site-packages\httpx\_client.py", line 1702, in _send_handling_auth
    response = await self._send_handling_redirects(
               ^^^^^^^^^^^^^^^^^^^^^^^^^^^^^^^^^^^^
  File "C:\Users\Admin\AppData\Local\Programs\Python\Python312\Lib\site-packages\httpx\_client.py", line 1739, in _send_handling_redirects
    response = await self._send_single_request(request)
               ^^^^^^^^^^^^^^^^^^^^^^^^^^^^^^^^^^^^^^^^
  File "C:\Users\Admin\AppData\Local\Programs\Python\Python312\Lib\site-packages\httpx\_client.py", line 1776, in _send_single_request
    response = await transport.handle_async_request(request)
               ^^^^^^^^^^^^^^^^^^^^^^^^^^^^^^^^^^^^^^^^^^^^^
  File "C:\Users\Admin\AppData\Local\Programs\Python\Python312\Lib\site-packages\httpx\_transports\default.py", line 376, in handle_async_request
    with map_httpcore_exceptions():
  File "C:\Users\Admin\AppData\Local\Programs\Python\Python312\Lib\contextlib.py", line 158, in __exit__
    self.gen.throw(value)
  File "C:\Users\Admin\AppData\Local\Programs\Python\Python312\Lib\site-packages\httpx\_transports\default.py", line 89, in map_httpcore_exceptions
    raise mapped_exc(message) from exc
httpx.ConnectError: [Errno 11001] getaddrinfo failed

The above exception was the direct cause of the following exception:

Traceback (most recent call last):
  File "C:\Users\Admin\AppData\Local\Programs\Python\Python312\Lib\site-packages\telegram\ext\_updater.py", line 750, in _network_loop_retry
    if not await do_action():
           ^^^^^^^^^^^^^^^^^
  File "C:\Users\Admin\AppData\Local\Programs\Python\Python312\Lib\site-packages\telegram\ext\_updater.py", line 744, in do_action
    return action_cb_task.result()
           ^^^^^^^^^^^^^^^^^^^^^^^
  File "C:\Users\Admin\AppData\Local\Programs\Python\Python312\Lib\asyncio\futures.py", line 203, in result
    raise self._exception.with_traceback(self._exception_tb)
  File "C:\Users\Admin\AppData\Local\Programs\Python\Python312\Lib\asyncio\tasks.py", line 316, in __step_run_and_handle_result
    result = coro.throw(exc)
             ^^^^^^^^^^^^^^^
  File "C:\Users\Admin\AppData\Local\Programs\Python\Python312\Lib\site-packages\telegram\ext\_updater.py", line 371, in polling_action_cb
    updates = await self.bot.get_updates(
              ^^^^^^^^^^^^^^^^^^^^^^^^^^^
  File "C:\Users\Admin\AppData\Local\Programs\Python\Python312\Lib\site-packages\telegram\ext\_extbot.py", line 650, in get_updates
    updates = await super().get_updates(
              ^^^^^^^^^^^^^^^^^^^^^^^^^^
  File "C:\Users\Admin\AppData\Local\Programs\Python\Python312\Lib\site-packages\telegram\_bot.py", line 4480, in get_updates
    await self._post(
  File "C:\Users\Admin\AppData\Local\Programs\Python\Python312\Lib\site-packages\telegram\_bot.py", line 619, in _post
    return await self._do_post(
           ^^^^^^^^^^^^^^^^^^^^
  File "C:\Users\Admin\AppData\Local\Programs\Python\Python312\Lib\site-packages\telegram\ext\_extbot.py", line 354, in _do_post
    return await super()._do_post(
           ^^^^^^^^^^^^^^^^^^^^^^^
  File "C:\Users\Admin\AppData\Local\Programs\Python\Python312\Lib\site-packages\telegram\_bot.py", line 648, in _do_post
    result = await request.post(
             ^^^^^^^^^^^^^^^^^^^
  File "C:\Users\Admin\AppData\Local\Programs\Python\Python312\Lib\site-packages\telegram\request\_baserequest.py", line 202, in post
    result = await self._request_wrapper(
             ^^^^^^^^^^^^^^^^^^^^^^^^^^^^
  File "C:\Users\Admin\AppData\Local\Programs\Python\Python312\Lib\site-packages\telegram\request\_baserequest.py", line 334, in _request_wrapper
    code, payload = await self.do_request(
                    ^^^^^^^^^^^^^^^^^^^^^^
  File "C:\Users\Admin\AppData\Local\Programs\Python\Python312\Lib\site-packages\telegram\request\_httpxrequest.py", line 317, in do_request
    raise NetworkError(f"httpx.{err.__class__.__name__}: {err}") from err
telegram.error.NetworkError: httpx.ConnectError: [Errno 11001] getaddrinfo failed
2024-12-21 22:38:04,239 - __main__ - ERROR - Обнаружена ошибка:
Traceback (most recent call last):
  File "C:\Users\Admin\AppData\Local\Programs\Python\Python312\Lib\site-packages\httpx\_transports\default.py", line 72, in map_httpcore_exceptions
    yield
  File "C:\Users\Admin\AppData\Local\Programs\Python\Python312\Lib\site-packages\httpx\_transports\default.py", line 377, in handle_async_request
    resp = await self._pool.handle_async_request(req)
           ^^^^^^^^^^^^^^^^^^^^^^^^^^^^^^^^^^^^^^^^^^
  File "C:\Users\Admin\AppData\Local\Programs\Python\Python312\Lib\site-packages\httpcore\_async\connection_pool.py", line 216, in handle_async_request
    raise exc from None
  File "C:\Users\Admin\AppData\Local\Programs\Python\Python312\Lib\site-packages\httpcore\_async\connection_pool.py", line 196, in handle_async_request
    response = await connection.handle_async_request(
               ^^^^^^^^^^^^^^^^^^^^^^^^^^^^^^^^^^^^^^
  File "C:\Users\Admin\AppData\Local\Programs\Python\Python312\Lib\site-packages\httpcore\_async\connection.py", line 99, in handle_async_request
    raise exc
  File "C:\Users\Admin\AppData\Local\Programs\Python\Python312\Lib\site-packages\httpcore\_async\connection.py", line 76, in handle_async_request
    stream = await self._connect(request)
             ^^^^^^^^^^^^^^^^^^^^^^^^^^^^
  File "C:\Users\Admin\AppData\Local\Programs\Python\Python312\Lib\site-packages\httpcore\_async\connection.py", line 122, in _connect
    stream = await self._network_backend.connect_tcp(**kwargs)
             ^^^^^^^^^^^^^^^^^^^^^^^^^^^^^^^^^^^^^^^^^^^^^^^^^
  File "C:\Users\Admin\AppData\Local\Programs\Python\Python312\Lib\site-packages\httpcore\_backends\auto.py", line 30, in connect_tcp
    return await self._backend.connect_tcp(
           ^^^^^^^^^^^^^^^^^^^^^^^^^^^^^^^^
  File "C:\Users\Admin\AppData\Local\Programs\Python\Python312\Lib\site-packages\httpcore\_backends\anyio.py", line 115, in connect_tcp
    with map_exceptions(exc_map):
  File "C:\Users\Admin\AppData\Local\Programs\Python\Python312\Lib\contextlib.py", line 158, in __exit__
    self.gen.throw(value)
  File "C:\Users\Admin\AppData\Local\Programs\Python\Python312\Lib\site-packages\httpcore\_exceptions.py", line 14, in map_exceptions
    raise to_exc(exc) from exc
httpcore.ConnectError: [Errno 11001] getaddrinfo failed

The above exception was the direct cause of the following exception:

Traceback (most recent call last):
  File "C:\Users\Admin\AppData\Local\Programs\Python\Python312\Lib\site-packages\telegram\request\_httpxrequest.py", line 293, in do_request
    res = await self._client.request(
          ^^^^^^^^^^^^^^^^^^^^^^^^^^^
  File "C:\Users\Admin\AppData\Local\Programs\Python\Python312\Lib\site-packages\httpx\_client.py", line 1585, in request
    return await self.send(request, auth=auth, follow_redirects=follow_redirects)
           ^^^^^^^^^^^^^^^^^^^^^^^^^^^^^^^^^^^^^^^^^^^^^^^^^^^^^^^^^^^^^^^^^^^^^^
  File "C:\Users\Admin\AppData\Local\Programs\Python\Python312\Lib\site-packages\httpx\_client.py", line 1674, in send
    response = await self._send_handling_auth(
               ^^^^^^^^^^^^^^^^^^^^^^^^^^^^^^^
  File "C:\Users\Admin\AppData\Local\Programs\Python\Python312\Lib\site-packages\httpx\_client.py", line 1702, in _send_handling_auth
    response = await self._send_handling_redirects(
               ^^^^^^^^^^^^^^^^^^^^^^^^^^^^^^^^^^^^
  File "C:\Users\Admin\AppData\Local\Programs\Python\Python312\Lib\site-packages\httpx\_client.py", line 1739, in _send_handling_redirects
    response = await self._send_single_request(request)
               ^^^^^^^^^^^^^^^^^^^^^^^^^^^^^^^^^^^^^^^^
  File "C:\Users\Admin\AppData\Local\Programs\Python\Python312\Lib\site-packages\httpx\_client.py", line 1776, in _send_single_request
    response = await transport.handle_async_request(request)
               ^^^^^^^^^^^^^^^^^^^^^^^^^^^^^^^^^^^^^^^^^^^^^
  File "C:\Users\Admin\AppData\Local\Programs\Python\Python312\Lib\site-packages\httpx\_transports\default.py", line 376, in handle_async_request
    with map_httpcore_exceptions():
  File "C:\Users\Admin\AppData\Local\Programs\Python\Python312\Lib\contextlib.py", line 158, in __exit__
    self.gen.throw(value)
  File "C:\Users\Admin\AppData\Local\Programs\Python\Python312\Lib\site-packages\httpx\_transports\default.py", line 89, in map_httpcore_exceptions
    raise mapped_exc(message) from exc
httpx.ConnectError: [Errno 11001] getaddrinfo failed

The above exception was the direct cause of the following exception:

Traceback (most recent call last):
  File "C:\Users\Admin\AppData\Local\Programs\Python\Python312\Lib\site-packages\telegram\ext\_updater.py", line 750, in _network_loop_retry
    if not await do_action():
           ^^^^^^^^^^^^^^^^^
  File "C:\Users\Admin\AppData\Local\Programs\Python\Python312\Lib\site-packages\telegram\ext\_updater.py", line 744, in do_action
    return action_cb_task.result()
           ^^^^^^^^^^^^^^^^^^^^^^^
  File "C:\Users\Admin\AppData\Local\Programs\Python\Python312\Lib\asyncio\futures.py", line 203, in result
    raise self._exception.with_traceback(self._exception_tb)
  File "C:\Users\Admin\AppData\Local\Programs\Python\Python312\Lib\asyncio\tasks.py", line 316, in __step_run_and_handle_result
    result = coro.throw(exc)
             ^^^^^^^^^^^^^^^
  File "C:\Users\Admin\AppData\Local\Programs\Python\Python312\Lib\site-packages\telegram\ext\_updater.py", line 371, in polling_action_cb
    updates = await self.bot.get_updates(
              ^^^^^^^^^^^^^^^^^^^^^^^^^^^
  File "C:\Users\Admin\AppData\Local\Programs\Python\Python312\Lib\site-packages\telegram\ext\_extbot.py", line 650, in get_updates
    updates = await super().get_updates(
              ^^^^^^^^^^^^^^^^^^^^^^^^^^
  File "C:\Users\Admin\AppData\Local\Programs\Python\Python312\Lib\site-packages\telegram\_bot.py", line 4480, in get_updates
    await self._post(
  File "C:\Users\Admin\AppData\Local\Programs\Python\Python312\Lib\site-packages\telegram\_bot.py", line 619, in _post
    return await self._do_post(
           ^^^^^^^^^^^^^^^^^^^^
  File "C:\Users\Admin\AppData\Local\Programs\Python\Python312\Lib\site-packages\telegram\ext\_extbot.py", line 354, in _do_post
    return await super()._do_post(
           ^^^^^^^^^^^^^^^^^^^^^^^
  File "C:\Users\Admin\AppData\Local\Programs\Python\Python312\Lib\site-packages\telegram\_bot.py", line 648, in _do_post
    result = await request.post(
             ^^^^^^^^^^^^^^^^^^^
  File "C:\Users\Admin\AppData\Local\Programs\Python\Python312\Lib\site-packages\telegram\request\_baserequest.py", line 202, in post
    result = await self._request_wrapper(
             ^^^^^^^^^^^^^^^^^^^^^^^^^^^^
  File "C:\Users\Admin\AppData\Local\Programs\Python\Python312\Lib\site-packages\telegram\request\_baserequest.py", line 334, in _request_wrapper
    code, payload = await self.do_request(
                    ^^^^^^^^^^^^^^^^^^^^^^
  File "C:\Users\Admin\AppData\Local\Programs\Python\Python312\Lib\site-packages\telegram\request\_httpxrequest.py", line 317, in do_request
    raise NetworkError(f"httpx.{err.__class__.__name__}: {err}") from err
telegram.error.NetworkError: httpx.ConnectError: [Errno 11001] getaddrinfo failed
2024-12-21 22:38:06,501 - __main__ - ERROR - Обнаружена ошибка:
Traceback (most recent call last):
  File "C:\Users\Admin\AppData\Local\Programs\Python\Python312\Lib\site-packages\httpx\_transports\default.py", line 72, in map_httpcore_exceptions
    yield
  File "C:\Users\Admin\AppData\Local\Programs\Python\Python312\Lib\site-packages\httpx\_transports\default.py", line 377, in handle_async_request
    resp = await self._pool.handle_async_request(req)
           ^^^^^^^^^^^^^^^^^^^^^^^^^^^^^^^^^^^^^^^^^^
  File "C:\Users\Admin\AppData\Local\Programs\Python\Python312\Lib\site-packages\httpcore\_async\connection_pool.py", line 216, in handle_async_request
    raise exc from None
  File "C:\Users\Admin\AppData\Local\Programs\Python\Python312\Lib\site-packages\httpcore\_async\connection_pool.py", line 196, in handle_async_request
    response = await connection.handle_async_request(
               ^^^^^^^^^^^^^^^^^^^^^^^^^^^^^^^^^^^^^^
  File "C:\Users\Admin\AppData\Local\Programs\Python\Python312\Lib\site-packages\httpcore\_async\connection.py", line 99, in handle_async_request
    raise exc
  File "C:\Users\Admin\AppData\Local\Programs\Python\Python312\Lib\site-packages\httpcore\_async\connection.py", line 76, in handle_async_request
    stream = await self._connect(request)
             ^^^^^^^^^^^^^^^^^^^^^^^^^^^^
  File "C:\Users\Admin\AppData\Local\Programs\Python\Python312\Lib\site-packages\httpcore\_async\connection.py", line 122, in _connect
    stream = await self._network_backend.connect_tcp(**kwargs)
             ^^^^^^^^^^^^^^^^^^^^^^^^^^^^^^^^^^^^^^^^^^^^^^^^^
  File "C:\Users\Admin\AppData\Local\Programs\Python\Python312\Lib\site-packages\httpcore\_backends\auto.py", line 30, in connect_tcp
    return await self._backend.connect_tcp(
           ^^^^^^^^^^^^^^^^^^^^^^^^^^^^^^^^
  File "C:\Users\Admin\AppData\Local\Programs\Python\Python312\Lib\site-packages\httpcore\_backends\anyio.py", line 115, in connect_tcp
    with map_exceptions(exc_map):
  File "C:\Users\Admin\AppData\Local\Programs\Python\Python312\Lib\contextlib.py", line 158, in __exit__
    self.gen.throw(value)
  File "C:\Users\Admin\AppData\Local\Programs\Python\Python312\Lib\site-packages\httpcore\_exceptions.py", line 14, in map_exceptions
    raise to_exc(exc) from exc
httpcore.ConnectError: [Errno 11001] getaddrinfo failed

The above exception was the direct cause of the following exception:

Traceback (most recent call last):
  File "C:\Users\Admin\AppData\Local\Programs\Python\Python312\Lib\site-packages\telegram\request\_httpxrequest.py", line 293, in do_request
    res = await self._client.request(
          ^^^^^^^^^^^^^^^^^^^^^^^^^^^
  File "C:\Users\Admin\AppData\Local\Programs\Python\Python312\Lib\site-packages\httpx\_client.py", line 1585, in request
    return await self.send(request, auth=auth, follow_redirects=follow_redirects)
           ^^^^^^^^^^^^^^^^^^^^^^^^^^^^^^^^^^^^^^^^^^^^^^^^^^^^^^^^^^^^^^^^^^^^^^
  File "C:\Users\Admin\AppData\Local\Programs\Python\Python312\Lib\site-packages\httpx\_client.py", line 1674, in send
    response = await self._send_handling_auth(
               ^^^^^^^^^^^^^^^^^^^^^^^^^^^^^^^
  File "C:\Users\Admin\AppData\Local\Programs\Python\Python312\Lib\site-packages\httpx\_client.py", line 1702, in _send_handling_auth
    response = await self._send_handling_redirects(
               ^^^^^^^^^^^^^^^^^^^^^^^^^^^^^^^^^^^^
  File "C:\Users\Admin\AppData\Local\Programs\Python\Python312\Lib\site-packages\httpx\_client.py", line 1739, in _send_handling_redirects
    response = await self._send_single_request(request)
               ^^^^^^^^^^^^^^^^^^^^^^^^^^^^^^^^^^^^^^^^
  File "C:\Users\Admin\AppData\Local\Programs\Python\Python312\Lib\site-packages\httpx\_client.py", line 1776, in _send_single_request
    response = await transport.handle_async_request(request)
               ^^^^^^^^^^^^^^^^^^^^^^^^^^^^^^^^^^^^^^^^^^^^^
  File "C:\Users\Admin\AppData\Local\Programs\Python\Python312\Lib\site-packages\httpx\_transports\default.py", line 376, in handle_async_request
    with map_httpcore_exceptions():
  File "C:\Users\Admin\AppData\Local\Programs\Python\Python312\Lib\contextlib.py", line 158, in __exit__
    self.gen.throw(value)
  File "C:\Users\Admin\AppData\Local\Programs\Python\Python312\Lib\site-packages\httpx\_transports\default.py", line 89, in map_httpcore_exceptions
    raise mapped_exc(message) from exc
httpx.ConnectError: [Errno 11001] getaddrinfo failed

The above exception was the direct cause of the following exception:

Traceback (most recent call last):
  File "C:\Users\Admin\AppData\Local\Programs\Python\Python312\Lib\site-packages\telegram\ext\_updater.py", line 750, in _network_loop_retry
    if not await do_action():
           ^^^^^^^^^^^^^^^^^
  File "C:\Users\Admin\AppData\Local\Programs\Python\Python312\Lib\site-packages\telegram\ext\_updater.py", line 744, in do_action
    return action_cb_task.result()
           ^^^^^^^^^^^^^^^^^^^^^^^
  File "C:\Users\Admin\AppData\Local\Programs\Python\Python312\Lib\asyncio\futures.py", line 203, in result
    raise self._exception.with_traceback(self._exception_tb)
  File "C:\Users\Admin\AppData\Local\Programs\Python\Python312\Lib\asyncio\tasks.py", line 316, in __step_run_and_handle_result
    result = coro.throw(exc)
             ^^^^^^^^^^^^^^^
  File "C:\Users\Admin\AppData\Local\Programs\Python\Python312\Lib\site-packages\telegram\ext\_updater.py", line 371, in polling_action_cb
    updates = await self.bot.get_updates(
              ^^^^^^^^^^^^^^^^^^^^^^^^^^^
  File "C:\Users\Admin\AppData\Local\Programs\Python\Python312\Lib\site-packages\telegram\ext\_extbot.py", line 650, in get_updates
    updates = await super().get_updates(
              ^^^^^^^^^^^^^^^^^^^^^^^^^^
  File "C:\Users\Admin\AppData\Local\Programs\Python\Python312\Lib\site-packages\telegram\_bot.py", line 4480, in get_updates
    await self._post(
  File "C:\Users\Admin\AppData\Local\Programs\Python\Python312\Lib\site-packages\telegram\_bot.py", line 619, in _post
    return await self._do_post(
           ^^^^^^^^^^^^^^^^^^^^
  File "C:\Users\Admin\AppData\Local\Programs\Python\Python312\Lib\site-packages\telegram\ext\_extbot.py", line 354, in _do_post
    return await super()._do_post(
           ^^^^^^^^^^^^^^^^^^^^^^^
  File "C:\Users\Admin\AppData\Local\Programs\Python\Python312\Lib\site-packages\telegram\_bot.py", line 648, in _do_post
    result = await request.post(
             ^^^^^^^^^^^^^^^^^^^
  File "C:\Users\Admin\AppData\Local\Programs\Python\Python312\Lib\site-packages\telegram\request\_baserequest.py", line 202, in post
    result = await self._request_wrapper(
             ^^^^^^^^^^^^^^^^^^^^^^^^^^^^
  File "C:\Users\Admin\AppData\Local\Programs\Python\Python312\Lib\site-packages\telegram\request\_baserequest.py", line 334, in _request_wrapper
    code, payload = await self.do_request(
                    ^^^^^^^^^^^^^^^^^^^^^^
  File "C:\Users\Admin\AppData\Local\Programs\Python\Python312\Lib\site-packages\telegram\request\_httpxrequest.py", line 317, in do_request
    raise NetworkError(f"httpx.{err.__class__.__name__}: {err}") from err
telegram.error.NetworkError: httpx.ConnectError: [Errno 11001] getaddrinfo failed
2024-12-21 22:38:09,880 - __main__ - ERROR - Обнаружена ошибка:
Traceback (most recent call last):
  File "C:\Users\Admin\AppData\Local\Programs\Python\Python312\Lib\site-packages\httpx\_transports\default.py", line 72, in map_httpcore_exceptions
    yield
  File "C:\Users\Admin\AppData\Local\Programs\Python\Python312\Lib\site-packages\httpx\_transports\default.py", line 377, in handle_async_request
    resp = await self._pool.handle_async_request(req)
           ^^^^^^^^^^^^^^^^^^^^^^^^^^^^^^^^^^^^^^^^^^
  File "C:\Users\Admin\AppData\Local\Programs\Python\Python312\Lib\site-packages\httpcore\_async\connection_pool.py", line 216, in handle_async_request
    raise exc from None
  File "C:\Users\Admin\AppData\Local\Programs\Python\Python312\Lib\site-packages\httpcore\_async\connection_pool.py", line 196, in handle_async_request
    response = await connection.handle_async_request(
               ^^^^^^^^^^^^^^^^^^^^^^^^^^^^^^^^^^^^^^
  File "C:\Users\Admin\AppData\Local\Programs\Python\Python312\Lib\site-packages\httpcore\_async\connection.py", line 99, in handle_async_request
    raise exc
  File "C:\Users\Admin\AppData\Local\Programs\Python\Python312\Lib\site-packages\httpcore\_async\connection.py", line 76, in handle_async_request
    stream = await self._connect(request)
             ^^^^^^^^^^^^^^^^^^^^^^^^^^^^
  File "C:\Users\Admin\AppData\Local\Programs\Python\Python312\Lib\site-packages\httpcore\_async\connection.py", line 122, in _connect
    stream = await self._network_backend.connect_tcp(**kwargs)
             ^^^^^^^^^^^^^^^^^^^^^^^^^^^^^^^^^^^^^^^^^^^^^^^^^
  File "C:\Users\Admin\AppData\Local\Programs\Python\Python312\Lib\site-packages\httpcore\_backends\auto.py", line 30, in connect_tcp
    return await self._backend.connect_tcp(
           ^^^^^^^^^^^^^^^^^^^^^^^^^^^^^^^^
  File "C:\Users\Admin\AppData\Local\Programs\Python\Python312\Lib\site-packages\httpcore\_backends\anyio.py", line 115, in connect_tcp
    with map_exceptions(exc_map):
  File "C:\Users\Admin\AppData\Local\Programs\Python\Python312\Lib\contextlib.py", line 158, in __exit__
    self.gen.throw(value)
  File "C:\Users\Admin\AppData\Local\Programs\Python\Python312\Lib\site-packages\httpcore\_exceptions.py", line 14, in map_exceptions
    raise to_exc(exc) from exc
httpcore.ConnectError: [Errno 11001] getaddrinfo failed

The above exception was the direct cause of the following exception:

Traceback (most recent call last):
  File "C:\Users\Admin\AppData\Local\Programs\Python\Python312\Lib\site-packages\telegram\request\_httpxrequest.py", line 293, in do_request
    res = await self._client.request(
          ^^^^^^^^^^^^^^^^^^^^^^^^^^^
  File "C:\Users\Admin\AppData\Local\Programs\Python\Python312\Lib\site-packages\httpx\_client.py", line 1585, in request
    return await self.send(request, auth=auth, follow_redirects=follow_redirects)
           ^^^^^^^^^^^^^^^^^^^^^^^^^^^^^^^^^^^^^^^^^^^^^^^^^^^^^^^^^^^^^^^^^^^^^^
  File "C:\Users\Admin\AppData\Local\Programs\Python\Python312\Lib\site-packages\httpx\_client.py", line 1674, in send
    response = await self._send_handling_auth(
               ^^^^^^^^^^^^^^^^^^^^^^^^^^^^^^^
  File "C:\Users\Admin\AppData\Local\Programs\Python\Python312\Lib\site-packages\httpx\_client.py", line 1702, in _send_handling_auth
    response = await self._send_handling_redirects(
               ^^^^^^^^^^^^^^^^^^^^^^^^^^^^^^^^^^^^
  File "C:\Users\Admin\AppData\Local\Programs\Python\Python312\Lib\site-packages\httpx\_client.py", line 1739, in _send_handling_redirects
    response = await self._send_single_request(request)
               ^^^^^^^^^^^^^^^^^^^^^^^^^^^^^^^^^^^^^^^^
  File "C:\Users\Admin\AppData\Local\Programs\Python\Python312\Lib\site-packages\httpx\_client.py", line 1776, in _send_single_request
    response = await transport.handle_async_request(request)
               ^^^^^^^^^^^^^^^^^^^^^^^^^^^^^^^^^^^^^^^^^^^^^
  File "C:\Users\Admin\AppData\Local\Programs\Python\Python312\Lib\site-packages\httpx\_transports\default.py", line 376, in handle_async_request
    with map_httpcore_exceptions():
  File "C:\Users\Admin\AppData\Local\Programs\Python\Python312\Lib\contextlib.py", line 158, in __exit__
    self.gen.throw(value)
  File "C:\Users\Admin\AppData\Local\Programs\Python\Python312\Lib\site-packages\httpx\_transports\default.py", line 89, in map_httpcore_exceptions
    raise mapped_exc(message) from exc
httpx.ConnectError: [Errno 11001] getaddrinfo failed

The above exception was the direct cause of the following exception:

Traceback (most recent call last):
  File "C:\Users\Admin\AppData\Local\Programs\Python\Python312\Lib\site-packages\telegram\ext\_updater.py", line 750, in _network_loop_retry
    if not await do_action():
           ^^^^^^^^^^^^^^^^^
  File "C:\Users\Admin\AppData\Local\Programs\Python\Python312\Lib\site-packages\telegram\ext\_updater.py", line 744, in do_action
    return action_cb_task.result()
           ^^^^^^^^^^^^^^^^^^^^^^^
  File "C:\Users\Admin\AppData\Local\Programs\Python\Python312\Lib\asyncio\futures.py", line 203, in result
    raise self._exception.with_traceback(self._exception_tb)
  File "C:\Users\Admin\AppData\Local\Programs\Python\Python312\Lib\asyncio\tasks.py", line 316, in __step_run_and_handle_result
    result = coro.throw(exc)
             ^^^^^^^^^^^^^^^
  File "C:\Users\Admin\AppData\Local\Programs\Python\Python312\Lib\site-packages\telegram\ext\_updater.py", line 371, in polling_action_cb
    updates = await self.bot.get_updates(
              ^^^^^^^^^^^^^^^^^^^^^^^^^^^
  File "C:\Users\Admin\AppData\Local\Programs\Python\Python312\Lib\site-packages\telegram\ext\_extbot.py", line 650, in get_updates
    updates = await super().get_updates(
              ^^^^^^^^^^^^^^^^^^^^^^^^^^
  File "C:\Users\Admin\AppData\Local\Programs\Python\Python312\Lib\site-packages\telegram\_bot.py", line 4480, in get_updates
    await self._post(
  File "C:\Users\Admin\AppData\Local\Programs\Python\Python312\Lib\site-packages\telegram\_bot.py", line 619, in _post
    return await self._do_post(
           ^^^^^^^^^^^^^^^^^^^^
  File "C:\Users\Admin\AppData\Local\Programs\Python\Python312\Lib\site-packages\telegram\ext\_extbot.py", line 354, in _do_post
    return await super()._do_post(
           ^^^^^^^^^^^^^^^^^^^^^^^
  File "C:\Users\Admin\AppData\Local\Programs\Python\Python312\Lib\site-packages\telegram\_bot.py", line 648, in _do_post
    result = await request.post(
             ^^^^^^^^^^^^^^^^^^^
  File "C:\Users\Admin\AppData\Local\Programs\Python\Python312\Lib\site-packages\telegram\request\_baserequest.py", line 202, in post
    result = await self._request_wrapper(
             ^^^^^^^^^^^^^^^^^^^^^^^^^^^^
  File "C:\Users\Admin\AppData\Local\Programs\Python\Python312\Lib\site-packages\telegram\request\_baserequest.py", line 334, in _request_wrapper
    code, payload = await self.do_request(
                    ^^^^^^^^^^^^^^^^^^^^^^
  File "C:\Users\Admin\AppData\Local\Programs\Python\Python312\Lib\site-packages\telegram\request\_httpxrequest.py", line 317, in do_request
    raise NetworkError(f"httpx.{err.__class__.__name__}: {err}") from err
telegram.error.NetworkError: httpx.ConnectError: [Errno 11001] getaddrinfo failed
2024-12-21 22:38:14,947 - __main__ - ERROR - Обнаружена ошибка:
Traceback (most recent call last):
  File "C:\Users\Admin\AppData\Local\Programs\Python\Python312\Lib\site-packages\httpx\_transports\default.py", line 72, in map_httpcore_exceptions
    yield
  File "C:\Users\Admin\AppData\Local\Programs\Python\Python312\Lib\site-packages\httpx\_transports\default.py", line 377, in handle_async_request
    resp = await self._pool.handle_async_request(req)
           ^^^^^^^^^^^^^^^^^^^^^^^^^^^^^^^^^^^^^^^^^^
  File "C:\Users\Admin\AppData\Local\Programs\Python\Python312\Lib\site-packages\httpcore\_async\connection_pool.py", line 216, in handle_async_request
    raise exc from None
  File "C:\Users\Admin\AppData\Local\Programs\Python\Python312\Lib\site-packages\httpcore\_async\connection_pool.py", line 196, in handle_async_request
    response = await connection.handle_async_request(
               ^^^^^^^^^^^^^^^^^^^^^^^^^^^^^^^^^^^^^^
  File "C:\Users\Admin\AppData\Local\Programs\Python\Python312\Lib\site-packages\httpcore\_async\connection.py", line 99, in handle_async_request
    raise exc
  File "C:\Users\Admin\AppData\Local\Programs\Python\Python312\Lib\site-packages\httpcore\_async\connection.py", line 76, in handle_async_request
    stream = await self._connect(request)
             ^^^^^^^^^^^^^^^^^^^^^^^^^^^^
  File "C:\Users\Admin\AppData\Local\Programs\Python\Python312\Lib\site-packages\httpcore\_async\connection.py", line 122, in _connect
    stream = await self._network_backend.connect_tcp(**kwargs)
             ^^^^^^^^^^^^^^^^^^^^^^^^^^^^^^^^^^^^^^^^^^^^^^^^^
  File "C:\Users\Admin\AppData\Local\Programs\Python\Python312\Lib\site-packages\httpcore\_backends\auto.py", line 30, in connect_tcp
    return await self._backend.connect_tcp(
           ^^^^^^^^^^^^^^^^^^^^^^^^^^^^^^^^
  File "C:\Users\Admin\AppData\Local\Programs\Python\Python312\Lib\site-packages\httpcore\_backends\anyio.py", line 115, in connect_tcp
    with map_exceptions(exc_map):
  File "C:\Users\Admin\AppData\Local\Programs\Python\Python312\Lib\contextlib.py", line 158, in __exit__
    self.gen.throw(value)
  File "C:\Users\Admin\AppData\Local\Programs\Python\Python312\Lib\site-packages\httpcore\_exceptions.py", line 14, in map_exceptions
    raise to_exc(exc) from exc
httpcore.ConnectError: [Errno 11001] getaddrinfo failed

The above exception was the direct cause of the following exception:

Traceback (most recent call last):
  File "C:\Users\Admin\AppData\Local\Programs\Python\Python312\Lib\site-packages\telegram\request\_httpxrequest.py", line 293, in do_request
    res = await self._client.request(
          ^^^^^^^^^^^^^^^^^^^^^^^^^^^
  File "C:\Users\Admin\AppData\Local\Programs\Python\Python312\Lib\site-packages\httpx\_client.py", line 1585, in request
    return await self.send(request, auth=auth, follow_redirects=follow_redirects)
           ^^^^^^^^^^^^^^^^^^^^^^^^^^^^^^^^^^^^^^^^^^^^^^^^^^^^^^^^^^^^^^^^^^^^^^
  File "C:\Users\Admin\AppData\Local\Programs\Python\Python312\Lib\site-packages\httpx\_client.py", line 1674, in send
    response = await self._send_handling_auth(
               ^^^^^^^^^^^^^^^^^^^^^^^^^^^^^^^
  File "C:\Users\Admin\AppData\Local\Programs\Python\Python312\Lib\site-packages\httpx\_client.py", line 1702, in _send_handling_auth
    response = await self._send_handling_redirects(
               ^^^^^^^^^^^^^^^^^^^^^^^^^^^^^^^^^^^^
  File "C:\Users\Admin\AppData\Local\Programs\Python\Python312\Lib\site-packages\httpx\_client.py", line 1739, in _send_handling_redirects
    response = await self._send_single_request(request)
               ^^^^^^^^^^^^^^^^^^^^^^^^^^^^^^^^^^^^^^^^
  File "C:\Users\Admin\AppData\Local\Programs\Python\Python312\Lib\site-packages\httpx\_client.py", line 1776, in _send_single_request
    response = await transport.handle_async_request(request)
               ^^^^^^^^^^^^^^^^^^^^^^^^^^^^^^^^^^^^^^^^^^^^^
  File "C:\Users\Admin\AppData\Local\Programs\Python\Python312\Lib\site-packages\httpx\_transports\default.py", line 376, in handle_async_request
    with map_httpcore_exceptions():
  File "C:\Users\Admin\AppData\Local\Programs\Python\Python312\Lib\contextlib.py", line 158, in __exit__
    self.gen.throw(value)
  File "C:\Users\Admin\AppData\Local\Programs\Python\Python312\Lib\site-packages\httpx\_transports\default.py", line 89, in map_httpcore_exceptions
    raise mapped_exc(message) from exc
httpx.ConnectError: [Errno 11001] getaddrinfo failed

The above exception was the direct cause of the following exception:

Traceback (most recent call last):
  File "C:\Users\Admin\AppData\Local\Programs\Python\Python312\Lib\site-packages\telegram\ext\_updater.py", line 750, in _network_loop_retry
    if not await do_action():
           ^^^^^^^^^^^^^^^^^
  File "C:\Users\Admin\AppData\Local\Programs\Python\Python312\Lib\site-packages\telegram\ext\_updater.py", line 744, in do_action
    return action_cb_task.result()
           ^^^^^^^^^^^^^^^^^^^^^^^
  File "C:\Users\Admin\AppData\Local\Programs\Python\Python312\Lib\asyncio\futures.py", line 203, in result
    raise self._exception.with_traceback(self._exception_tb)
  File "C:\Users\Admin\AppData\Local\Programs\Python\Python312\Lib\asyncio\tasks.py", line 316, in __step_run_and_handle_result
    result = coro.throw(exc)
             ^^^^^^^^^^^^^^^
  File "C:\Users\Admin\AppData\Local\Programs\Python\Python312\Lib\site-packages\telegram\ext\_updater.py", line 371, in polling_action_cb
    updates = await self.bot.get_updates(
              ^^^^^^^^^^^^^^^^^^^^^^^^^^^
  File "C:\Users\Admin\AppData\Local\Programs\Python\Python312\Lib\site-packages\telegram\ext\_extbot.py", line 650, in get_updates
    updates = await super().get_updates(
              ^^^^^^^^^^^^^^^^^^^^^^^^^^
  File "C:\Users\Admin\AppData\Local\Programs\Python\Python312\Lib\site-packages\telegram\_bot.py", line 4480, in get_updates
    await self._post(
  File "C:\Users\Admin\AppData\Local\Programs\Python\Python312\Lib\site-packages\telegram\_bot.py", line 619, in _post
    return await self._do_post(
           ^^^^^^^^^^^^^^^^^^^^
  File "C:\Users\Admin\AppData\Local\Programs\Python\Python312\Lib\site-packages\telegram\ext\_extbot.py", line 354, in _do_post
    return await super()._do_post(
           ^^^^^^^^^^^^^^^^^^^^^^^
  File "C:\Users\Admin\AppData\Local\Programs\Python\Python312\Lib\site-packages\telegram\_bot.py", line 648, in _do_post
    result = await request.post(
             ^^^^^^^^^^^^^^^^^^^
  File "C:\Users\Admin\AppData\Local\Programs\Python\Python312\Lib\site-packages\telegram\request\_baserequest.py", line 202, in post
    result = await self._request_wrapper(
             ^^^^^^^^^^^^^^^^^^^^^^^^^^^^
  File "C:\Users\Admin\AppData\Local\Programs\Python\Python312\Lib\site-packages\telegram\request\_baserequest.py", line 334, in _request_wrapper
    code, payload = await self.do_request(
                    ^^^^^^^^^^^^^^^^^^^^^^
  File "C:\Users\Admin\AppData\Local\Programs\Python\Python312\Lib\site-packages\telegram\request\_httpxrequest.py", line 317, in do_request
    raise NetworkError(f"httpx.{err.__class__.__name__}: {err}") from err
telegram.error.NetworkError: httpx.ConnectError: [Errno 11001] getaddrinfo failed
2024-12-21 22:38:22,567 - __main__ - ERROR - Обнаружена ошибка:
Traceback (most recent call last):
  File "C:\Users\Admin\AppData\Local\Programs\Python\Python312\Lib\site-packages\httpx\_transports\default.py", line 72, in map_httpcore_exceptions
    yield
  File "C:\Users\Admin\AppData\Local\Programs\Python\Python312\Lib\site-packages\httpx\_transports\default.py", line 377, in handle_async_request
    resp = await self._pool.handle_async_request(req)
           ^^^^^^^^^^^^^^^^^^^^^^^^^^^^^^^^^^^^^^^^^^
  File "C:\Users\Admin\AppData\Local\Programs\Python\Python312\Lib\site-packages\httpcore\_async\connection_pool.py", line 216, in handle_async_request
    raise exc from None
  File "C:\Users\Admin\AppData\Local\Programs\Python\Python312\Lib\site-packages\httpcore\_async\connection_pool.py", line 196, in handle_async_request
    response = await connection.handle_async_request(
               ^^^^^^^^^^^^^^^^^^^^^^^^^^^^^^^^^^^^^^
  File "C:\Users\Admin\AppData\Local\Programs\Python\Python312\Lib\site-packages\httpcore\_async\connection.py", line 99, in handle_async_request
    raise exc
  File "C:\Users\Admin\AppData\Local\Programs\Python\Python312\Lib\site-packages\httpcore\_async\connection.py", line 76, in handle_async_request
    stream = await self._connect(request)
             ^^^^^^^^^^^^^^^^^^^^^^^^^^^^
  File "C:\Users\Admin\AppData\Local\Programs\Python\Python312\Lib\site-packages\httpcore\_async\connection.py", line 122, in _connect
    stream = await self._network_backend.connect_tcp(**kwargs)
             ^^^^^^^^^^^^^^^^^^^^^^^^^^^^^^^^^^^^^^^^^^^^^^^^^
  File "C:\Users\Admin\AppData\Local\Programs\Python\Python312\Lib\site-packages\httpcore\_backends\auto.py", line 30, in connect_tcp
    return await self._backend.connect_tcp(
           ^^^^^^^^^^^^^^^^^^^^^^^^^^^^^^^^
  File "C:\Users\Admin\AppData\Local\Programs\Python\Python312\Lib\site-packages\httpcore\_backends\anyio.py", line 115, in connect_tcp
    with map_exceptions(exc_map):
  File "C:\Users\Admin\AppData\Local\Programs\Python\Python312\Lib\contextlib.py", line 158, in __exit__
    self.gen.throw(value)
  File "C:\Users\Admin\AppData\Local\Programs\Python\Python312\Lib\site-packages\httpcore\_exceptions.py", line 14, in map_exceptions
    raise to_exc(exc) from exc
httpcore.ConnectError: [Errno 11001] getaddrinfo failed

The above exception was the direct cause of the following exception:

Traceback (most recent call last):
  File "C:\Users\Admin\AppData\Local\Programs\Python\Python312\Lib\site-packages\telegram\request\_httpxrequest.py", line 293, in do_request
    res = await self._client.request(
          ^^^^^^^^^^^^^^^^^^^^^^^^^^^
  File "C:\Users\Admin\AppData\Local\Programs\Python\Python312\Lib\site-packages\httpx\_client.py", line 1585, in request
    return await self.send(request, auth=auth, follow_redirects=follow_redirects)
           ^^^^^^^^^^^^^^^^^^^^^^^^^^^^^^^^^^^^^^^^^^^^^^^^^^^^^^^^^^^^^^^^^^^^^^
  File "C:\Users\Admin\AppData\Local\Programs\Python\Python312\Lib\site-packages\httpx\_client.py", line 1674, in send
    response = await self._send_handling_auth(
               ^^^^^^^^^^^^^^^^^^^^^^^^^^^^^^^
  File "C:\Users\Admin\AppData\Local\Programs\Python\Python312\Lib\site-packages\httpx\_client.py", line 1702, in _send_handling_auth
    response = await self._send_handling_redirects(
               ^^^^^^^^^^^^^^^^^^^^^^^^^^^^^^^^^^^^
  File "C:\Users\Admin\AppData\Local\Programs\Python\Python312\Lib\site-packages\httpx\_client.py", line 1739, in _send_handling_redirects
    response = await self._send_single_request(request)
               ^^^^^^^^^^^^^^^^^^^^^^^^^^^^^^^^^^^^^^^^
  File "C:\Users\Admin\AppData\Local\Programs\Python\Python312\Lib\site-packages\httpx\_client.py", line 1776, in _send_single_request
    response = await transport.handle_async_request(request)
               ^^^^^^^^^^^^^^^^^^^^^^^^^^^^^^^^^^^^^^^^^^^^^
  File "C:\Users\Admin\AppData\Local\Programs\Python\Python312\Lib\site-packages\httpx\_transports\default.py", line 376, in handle_async_request
    with map_httpcore_exceptions():
  File "C:\Users\Admin\AppData\Local\Programs\Python\Python312\Lib\contextlib.py", line 158, in __exit__
    self.gen.throw(value)
  File "C:\Users\Admin\AppData\Local\Programs\Python\Python312\Lib\site-packages\httpx\_transports\default.py", line 89, in map_httpcore_exceptions
    raise mapped_exc(message) from exc
httpx.ConnectError: [Errno 11001] getaddrinfo failed

The above exception was the direct cause of the following exception:

Traceback (most recent call last):
  File "C:\Users\Admin\AppData\Local\Programs\Python\Python312\Lib\site-packages\telegram\ext\_updater.py", line 750, in _network_loop_retry
    if not await do_action():
           ^^^^^^^^^^^^^^^^^
  File "C:\Users\Admin\AppData\Local\Programs\Python\Python312\Lib\site-packages\telegram\ext\_updater.py", line 744, in do_action
    return action_cb_task.result()
           ^^^^^^^^^^^^^^^^^^^^^^^
  File "C:\Users\Admin\AppData\Local\Programs\Python\Python312\Lib\asyncio\futures.py", line 203, in result
    raise self._exception.with_traceback(self._exception_tb)
  File "C:\Users\Admin\AppData\Local\Programs\Python\Python312\Lib\asyncio\tasks.py", line 316, in __step_run_and_handle_result
    result = coro.throw(exc)
             ^^^^^^^^^^^^^^^
  File "C:\Users\Admin\AppData\Local\Programs\Python\Python312\Lib\site-packages\telegram\ext\_updater.py", line 371, in polling_action_cb
    updates = await self.bot.get_updates(
              ^^^^^^^^^^^^^^^^^^^^^^^^^^^
  File "C:\Users\Admin\AppData\Local\Programs\Python\Python312\Lib\site-packages\telegram\ext\_extbot.py", line 650, in get_updates
    updates = await super().get_updates(
              ^^^^^^^^^^^^^^^^^^^^^^^^^^
  File "C:\Users\Admin\AppData\Local\Programs\Python\Python312\Lib\site-packages\telegram\_bot.py", line 4480, in get_updates
    await self._post(
  File "C:\Users\Admin\AppData\Local\Programs\Python\Python312\Lib\site-packages\telegram\_bot.py", line 619, in _post
    return await self._do_post(
           ^^^^^^^^^^^^^^^^^^^^
  File "C:\Users\Admin\AppData\Local\Programs\Python\Python312\Lib\site-packages\telegram\ext\_extbot.py", line 354, in _do_post
    return await super()._do_post(
           ^^^^^^^^^^^^^^^^^^^^^^^
  File "C:\Users\Admin\AppData\Local\Programs\Python\Python312\Lib\site-packages\telegram\_bot.py", line 648, in _do_post
    result = await request.post(
             ^^^^^^^^^^^^^^^^^^^
  File "C:\Users\Admin\AppData\Local\Programs\Python\Python312\Lib\site-packages\telegram\request\_baserequest.py", line 202, in post
    result = await self._request_wrapper(
             ^^^^^^^^^^^^^^^^^^^^^^^^^^^^
  File "C:\Users\Admin\AppData\Local\Programs\Python\Python312\Lib\site-packages\telegram\request\_baserequest.py", line 334, in _request_wrapper
    code, payload = await self.do_request(
                    ^^^^^^^^^^^^^^^^^^^^^^
  File "C:\Users\Admin\AppData\Local\Programs\Python\Python312\Lib\site-packages\telegram\request\_httpxrequest.py", line 317, in do_request
    raise NetworkError(f"httpx.{err.__class__.__name__}: {err}") from err
telegram.error.NetworkError: httpx.ConnectError: [Errno 11001] getaddrinfo failed
2024-12-21 22:38:33,966 - __main__ - ERROR - Обнаружена ошибка:
Traceback (most recent call last):
  File "C:\Users\Admin\AppData\Local\Programs\Python\Python312\Lib\site-packages\httpx\_transports\default.py", line 72, in map_httpcore_exceptions
    yield
  File "C:\Users\Admin\AppData\Local\Programs\Python\Python312\Lib\site-packages\httpx\_transports\default.py", line 377, in handle_async_request
    resp = await self._pool.handle_async_request(req)
           ^^^^^^^^^^^^^^^^^^^^^^^^^^^^^^^^^^^^^^^^^^
  File "C:\Users\Admin\AppData\Local\Programs\Python\Python312\Lib\site-packages\httpcore\_async\connection_pool.py", line 216, in handle_async_request
    raise exc from None
  File "C:\Users\Admin\AppData\Local\Programs\Python\Python312\Lib\site-packages\httpcore\_async\connection_pool.py", line 196, in handle_async_request
    response = await connection.handle_async_request(
               ^^^^^^^^^^^^^^^^^^^^^^^^^^^^^^^^^^^^^^
  File "C:\Users\Admin\AppData\Local\Programs\Python\Python312\Lib\site-packages\httpcore\_async\connection.py", line 99, in handle_async_request
    raise exc
  File "C:\Users\Admin\AppData\Local\Programs\Python\Python312\Lib\site-packages\httpcore\_async\connection.py", line 76, in handle_async_request
    stream = await self._connect(request)
             ^^^^^^^^^^^^^^^^^^^^^^^^^^^^
  File "C:\Users\Admin\AppData\Local\Programs\Python\Python312\Lib\site-packages\httpcore\_async\connection.py", line 122, in _connect
    stream = await self._network_backend.connect_tcp(**kwargs)
             ^^^^^^^^^^^^^^^^^^^^^^^^^^^^^^^^^^^^^^^^^^^^^^^^^
  File "C:\Users\Admin\AppData\Local\Programs\Python\Python312\Lib\site-packages\httpcore\_backends\auto.py", line 30, in connect_tcp
    return await self._backend.connect_tcp(
           ^^^^^^^^^^^^^^^^^^^^^^^^^^^^^^^^
  File "C:\Users\Admin\AppData\Local\Programs\Python\Python312\Lib\site-packages\httpcore\_backends\anyio.py", line 115, in connect_tcp
    with map_exceptions(exc_map):
  File "C:\Users\Admin\AppData\Local\Programs\Python\Python312\Lib\contextlib.py", line 158, in __exit__
    self.gen.throw(value)
  File "C:\Users\Admin\AppData\Local\Programs\Python\Python312\Lib\site-packages\httpcore\_exceptions.py", line 14, in map_exceptions
    raise to_exc(exc) from exc
httpcore.ConnectError: [Errno 11001] getaddrinfo failed

The above exception was the direct cause of the following exception:

Traceback (most recent call last):
  File "C:\Users\Admin\AppData\Local\Programs\Python\Python312\Lib\site-packages\telegram\request\_httpxrequest.py", line 293, in do_request
    res = await self._client.request(
          ^^^^^^^^^^^^^^^^^^^^^^^^^^^
  File "C:\Users\Admin\AppData\Local\Programs\Python\Python312\Lib\site-packages\httpx\_client.py", line 1585, in request
    return await self.send(request, auth=auth, follow_redirects=follow_redirects)
           ^^^^^^^^^^^^^^^^^^^^^^^^^^^^^^^^^^^^^^^^^^^^^^^^^^^^^^^^^^^^^^^^^^^^^^
  File "C:\Users\Admin\AppData\Local\Programs\Python\Python312\Lib\site-packages\httpx\_client.py", line 1674, in send
    response = await self._send_handling_auth(
               ^^^^^^^^^^^^^^^^^^^^^^^^^^^^^^^
  File "C:\Users\Admin\AppData\Local\Programs\Python\Python312\Lib\site-packages\httpx\_client.py", line 1702, in _send_handling_auth
    response = await self._send_handling_redirects(
               ^^^^^^^^^^^^^^^^^^^^^^^^^^^^^^^^^^^^
  File "C:\Users\Admin\AppData\Local\Programs\Python\Python312\Lib\site-packages\httpx\_client.py", line 1739, in _send_handling_redirects
    response = await self._send_single_request(request)
               ^^^^^^^^^^^^^^^^^^^^^^^^^^^^^^^^^^^^^^^^
  File "C:\Users\Admin\AppData\Local\Programs\Python\Python312\Lib\site-packages\httpx\_client.py", line 1776, in _send_single_request
    response = await transport.handle_async_request(request)
               ^^^^^^^^^^^^^^^^^^^^^^^^^^^^^^^^^^^^^^^^^^^^^
  File "C:\Users\Admin\AppData\Local\Programs\Python\Python312\Lib\site-packages\httpx\_transports\default.py", line 376, in handle_async_request
    with map_httpcore_exceptions():
  File "C:\Users\Admin\AppData\Local\Programs\Python\Python312\Lib\contextlib.py", line 158, in __exit__
    self.gen.throw(value)
  File "C:\Users\Admin\AppData\Local\Programs\Python\Python312\Lib\site-packages\httpx\_transports\default.py", line 89, in map_httpcore_exceptions
    raise mapped_exc(message) from exc
httpx.ConnectError: [Errno 11001] getaddrinfo failed

The above exception was the direct cause of the following exception:

Traceback (most recent call last):
  File "C:\Users\Admin\AppData\Local\Programs\Python\Python312\Lib\site-packages\telegram\ext\_updater.py", line 750, in _network_loop_retry
    if not await do_action():
           ^^^^^^^^^^^^^^^^^
  File "C:\Users\Admin\AppData\Local\Programs\Python\Python312\Lib\site-packages\telegram\ext\_updater.py", line 744, in do_action
    return action_cb_task.result()
           ^^^^^^^^^^^^^^^^^^^^^^^
  File "C:\Users\Admin\AppData\Local\Programs\Python\Python312\Lib\asyncio\futures.py", line 203, in result
    raise self._exception.with_traceback(self._exception_tb)
  File "C:\Users\Admin\AppData\Local\Programs\Python\Python312\Lib\asyncio\tasks.py", line 316, in __step_run_and_handle_result
    result = coro.throw(exc)
             ^^^^^^^^^^^^^^^
  File "C:\Users\Admin\AppData\Local\Programs\Python\Python312\Lib\site-packages\telegram\ext\_updater.py", line 371, in polling_action_cb
    updates = await self.bot.get_updates(
              ^^^^^^^^^^^^^^^^^^^^^^^^^^^
  File "C:\Users\Admin\AppData\Local\Programs\Python\Python312\Lib\site-packages\telegram\ext\_extbot.py", line 650, in get_updates
    updates = await super().get_updates(
              ^^^^^^^^^^^^^^^^^^^^^^^^^^
  File "C:\Users\Admin\AppData\Local\Programs\Python\Python312\Lib\site-packages\telegram\_bot.py", line 4480, in get_updates
    await self._post(
  File "C:\Users\Admin\AppData\Local\Programs\Python\Python312\Lib\site-packages\telegram\_bot.py", line 619, in _post
    return await self._do_post(
           ^^^^^^^^^^^^^^^^^^^^
  File "C:\Users\Admin\AppData\Local\Programs\Python\Python312\Lib\site-packages\telegram\ext\_extbot.py", line 354, in _do_post
    return await super()._do_post(
           ^^^^^^^^^^^^^^^^^^^^^^^
  File "C:\Users\Admin\AppData\Local\Programs\Python\Python312\Lib\site-packages\telegram\_bot.py", line 648, in _do_post
    result = await request.post(
             ^^^^^^^^^^^^^^^^^^^
  File "C:\Users\Admin\AppData\Local\Programs\Python\Python312\Lib\site-packages\telegram\request\_baserequest.py", line 202, in post
    result = await self._request_wrapper(
             ^^^^^^^^^^^^^^^^^^^^^^^^^^^^
  File "C:\Users\Admin\AppData\Local\Programs\Python\Python312\Lib\site-packages\telegram\request\_baserequest.py", line 334, in _request_wrapper
    code, payload = await self.do_request(
                    ^^^^^^^^^^^^^^^^^^^^^^
  File "C:\Users\Admin\AppData\Local\Programs\Python\Python312\Lib\site-packages\telegram\request\_httpxrequest.py", line 317, in do_request
    raise NetworkError(f"httpx.{err.__class__.__name__}: {err}") from err
telegram.error.NetworkError: httpx.ConnectError: [Errno 11001] getaddrinfo failed
2024-12-21 22:38:51,074 - __main__ - ERROR - Обнаружена ошибка:
Traceback (most recent call last):
  File "C:\Users\Admin\AppData\Local\Programs\Python\Python312\Lib\site-packages\httpx\_transports\default.py", line 72, in map_httpcore_exceptions
    yield
  File "C:\Users\Admin\AppData\Local\Programs\Python\Python312\Lib\site-packages\httpx\_transports\default.py", line 377, in handle_async_request
    resp = await self._pool.handle_async_request(req)
           ^^^^^^^^^^^^^^^^^^^^^^^^^^^^^^^^^^^^^^^^^^
  File "C:\Users\Admin\AppData\Local\Programs\Python\Python312\Lib\site-packages\httpcore\_async\connection_pool.py", line 216, in handle_async_request
    raise exc from None
  File "C:\Users\Admin\AppData\Local\Programs\Python\Python312\Lib\site-packages\httpcore\_async\connection_pool.py", line 196, in handle_async_request
    response = await connection.handle_async_request(
               ^^^^^^^^^^^^^^^^^^^^^^^^^^^^^^^^^^^^^^
  File "C:\Users\Admin\AppData\Local\Programs\Python\Python312\Lib\site-packages\httpcore\_async\connection.py", line 99, in handle_async_request
    raise exc
  File "C:\Users\Admin\AppData\Local\Programs\Python\Python312\Lib\site-packages\httpcore\_async\connection.py", line 76, in handle_async_request
    stream = await self._connect(request)
             ^^^^^^^^^^^^^^^^^^^^^^^^^^^^
  File "C:\Users\Admin\AppData\Local\Programs\Python\Python312\Lib\site-packages\httpcore\_async\connection.py", line 122, in _connect
    stream = await self._network_backend.connect_tcp(**kwargs)
             ^^^^^^^^^^^^^^^^^^^^^^^^^^^^^^^^^^^^^^^^^^^^^^^^^
  File "C:\Users\Admin\AppData\Local\Programs\Python\Python312\Lib\site-packages\httpcore\_backends\auto.py", line 30, in connect_tcp
    return await self._backend.connect_tcp(
           ^^^^^^^^^^^^^^^^^^^^^^^^^^^^^^^^
  File "C:\Users\Admin\AppData\Local\Programs\Python\Python312\Lib\site-packages\httpcore\_backends\anyio.py", line 115, in connect_tcp
    with map_exceptions(exc_map):
  File "C:\Users\Admin\AppData\Local\Programs\Python\Python312\Lib\contextlib.py", line 158, in __exit__
    self.gen.throw(value)
  File "C:\Users\Admin\AppData\Local\Programs\Python\Python312\Lib\site-packages\httpcore\_exceptions.py", line 14, in map_exceptions
    raise to_exc(exc) from exc
httpcore.ConnectError: [Errno 11001] getaddrinfo failed

The above exception was the direct cause of the following exception:

Traceback (most recent call last):
  File "C:\Users\Admin\AppData\Local\Programs\Python\Python312\Lib\site-packages\telegram\request\_httpxrequest.py", line 293, in do_request
    res = await self._client.request(
          ^^^^^^^^^^^^^^^^^^^^^^^^^^^
  File "C:\Users\Admin\AppData\Local\Programs\Python\Python312\Lib\site-packages\httpx\_client.py", line 1585, in request
    return await self.send(request, auth=auth, follow_redirects=follow_redirects)
           ^^^^^^^^^^^^^^^^^^^^^^^^^^^^^^^^^^^^^^^^^^^^^^^^^^^^^^^^^^^^^^^^^^^^^^
  File "C:\Users\Admin\AppData\Local\Programs\Python\Python312\Lib\site-packages\httpx\_client.py", line 1674, in send
    response = await self._send_handling_auth(
               ^^^^^^^^^^^^^^^^^^^^^^^^^^^^^^^
  File "C:\Users\Admin\AppData\Local\Programs\Python\Python312\Lib\site-packages\httpx\_client.py", line 1702, in _send_handling_auth
    response = await self._send_handling_redirects(
               ^^^^^^^^^^^^^^^^^^^^^^^^^^^^^^^^^^^^
  File "C:\Users\Admin\AppData\Local\Programs\Python\Python312\Lib\site-packages\httpx\_client.py", line 1739, in _send_handling_redirects
    response = await self._send_single_request(request)
               ^^^^^^^^^^^^^^^^^^^^^^^^^^^^^^^^^^^^^^^^
  File "C:\Users\Admin\AppData\Local\Programs\Python\Python312\Lib\site-packages\httpx\_client.py", line 1776, in _send_single_request
    response = await transport.handle_async_request(request)
               ^^^^^^^^^^^^^^^^^^^^^^^^^^^^^^^^^^^^^^^^^^^^^
  File "C:\Users\Admin\AppData\Local\Programs\Python\Python312\Lib\site-packages\httpx\_transports\default.py", line 376, in handle_async_request
    with map_httpcore_exceptions():
  File "C:\Users\Admin\AppData\Local\Programs\Python\Python312\Lib\contextlib.py", line 158, in __exit__
    self.gen.throw(value)
  File "C:\Users\Admin\AppData\Local\Programs\Python\Python312\Lib\site-packages\httpx\_transports\default.py", line 89, in map_httpcore_exceptions
    raise mapped_exc(message) from exc
httpx.ConnectError: [Errno 11001] getaddrinfo failed

The above exception was the direct cause of the following exception:

Traceback (most recent call last):
  File "C:\Users\Admin\AppData\Local\Programs\Python\Python312\Lib\site-packages\telegram\ext\_updater.py", line 750, in _network_loop_retry
    if not await do_action():
           ^^^^^^^^^^^^^^^^^
  File "C:\Users\Admin\AppData\Local\Programs\Python\Python312\Lib\site-packages\telegram\ext\_updater.py", line 744, in do_action
    return action_cb_task.result()
           ^^^^^^^^^^^^^^^^^^^^^^^
  File "C:\Users\Admin\AppData\Local\Programs\Python\Python312\Lib\asyncio\futures.py", line 203, in result
    raise self._exception.with_traceback(self._exception_tb)
  File "C:\Users\Admin\AppData\Local\Programs\Python\Python312\Lib\asyncio\tasks.py", line 316, in __step_run_and_handle_result
    result = coro.throw(exc)
             ^^^^^^^^^^^^^^^
  File "C:\Users\Admin\AppData\Local\Programs\Python\Python312\Lib\site-packages\telegram\ext\_updater.py", line 371, in polling_action_cb
    updates = await self.bot.get_updates(
              ^^^^^^^^^^^^^^^^^^^^^^^^^^^
  File "C:\Users\Admin\AppData\Local\Programs\Python\Python312\Lib\site-packages\telegram\ext\_extbot.py", line 650, in get_updates
    updates = await super().get_updates(
              ^^^^^^^^^^^^^^^^^^^^^^^^^^
  File "C:\Users\Admin\AppData\Local\Programs\Python\Python312\Lib\site-packages\telegram\_bot.py", line 4480, in get_updates
    await self._post(
  File "C:\Users\Admin\AppData\Local\Programs\Python\Python312\Lib\site-packages\telegram\_bot.py", line 619, in _post
    return await self._do_post(
           ^^^^^^^^^^^^^^^^^^^^
  File "C:\Users\Admin\AppData\Local\Programs\Python\Python312\Lib\site-packages\telegram\ext\_extbot.py", line 354, in _do_post
    return await super()._do_post(
           ^^^^^^^^^^^^^^^^^^^^^^^
  File "C:\Users\Admin\AppData\Local\Programs\Python\Python312\Lib\site-packages\telegram\_bot.py", line 648, in _do_post
    result = await request.post(
             ^^^^^^^^^^^^^^^^^^^
  File "C:\Users\Admin\AppData\Local\Programs\Python\Python312\Lib\site-packages\telegram\request\_baserequest.py", line 202, in post
    result = await self._request_wrapper(
             ^^^^^^^^^^^^^^^^^^^^^^^^^^^^
  File "C:\Users\Admin\AppData\Local\Programs\Python\Python312\Lib\site-packages\telegram\request\_baserequest.py", line 334, in _request_wrapper
    code, payload = await self.do_request(
                    ^^^^^^^^^^^^^^^^^^^^^^
  File "C:\Users\Admin\AppData\Local\Programs\Python\Python312\Lib\site-packages\telegram\request\_httpxrequest.py", line 317, in do_request
    raise NetworkError(f"httpx.{err.__class__.__name__}: {err}") from err
telegram.error.NetworkError: httpx.ConnectError: [Errno 11001] getaddrinfo failed
2024-12-21 22:39:16,722 - __main__ - ERROR - Обнаружена ошибка:
Traceback (most recent call last):
  File "C:\Users\Admin\AppData\Local\Programs\Python\Python312\Lib\site-packages\httpx\_transports\default.py", line 72, in map_httpcore_exceptions
    yield
  File "C:\Users\Admin\AppData\Local\Programs\Python\Python312\Lib\site-packages\httpx\_transports\default.py", line 377, in handle_async_request
    resp = await self._pool.handle_async_request(req)
           ^^^^^^^^^^^^^^^^^^^^^^^^^^^^^^^^^^^^^^^^^^
  File "C:\Users\Admin\AppData\Local\Programs\Python\Python312\Lib\site-packages\httpcore\_async\connection_pool.py", line 216, in handle_async_request
    raise exc from None
  File "C:\Users\Admin\AppData\Local\Programs\Python\Python312\Lib\site-packages\httpcore\_async\connection_pool.py", line 196, in handle_async_request
    response = await connection.handle_async_request(
               ^^^^^^^^^^^^^^^^^^^^^^^^^^^^^^^^^^^^^^
  File "C:\Users\Admin\AppData\Local\Programs\Python\Python312\Lib\site-packages\httpcore\_async\connection.py", line 99, in handle_async_request
    raise exc
  File "C:\Users\Admin\AppData\Local\Programs\Python\Python312\Lib\site-packages\httpcore\_async\connection.py", line 76, in handle_async_request
    stream = await self._connect(request)
             ^^^^^^^^^^^^^^^^^^^^^^^^^^^^
  File "C:\Users\Admin\AppData\Local\Programs\Python\Python312\Lib\site-packages\httpcore\_async\connection.py", line 122, in _connect
    stream = await self._network_backend.connect_tcp(**kwargs)
             ^^^^^^^^^^^^^^^^^^^^^^^^^^^^^^^^^^^^^^^^^^^^^^^^^
  File "C:\Users\Admin\AppData\Local\Programs\Python\Python312\Lib\site-packages\httpcore\_backends\auto.py", line 30, in connect_tcp
    return await self._backend.connect_tcp(
           ^^^^^^^^^^^^^^^^^^^^^^^^^^^^^^^^
  File "C:\Users\Admin\AppData\Local\Programs\Python\Python312\Lib\site-packages\httpcore\_backends\anyio.py", line 115, in connect_tcp
    with map_exceptions(exc_map):
  File "C:\Users\Admin\AppData\Local\Programs\Python\Python312\Lib\contextlib.py", line 158, in __exit__
    self.gen.throw(value)
  File "C:\Users\Admin\AppData\Local\Programs\Python\Python312\Lib\site-packages\httpcore\_exceptions.py", line 14, in map_exceptions
    raise to_exc(exc) from exc
httpcore.ConnectError: [Errno 11001] getaddrinfo failed

The above exception was the direct cause of the following exception:

Traceback (most recent call last):
  File "C:\Users\Admin\AppData\Local\Programs\Python\Python312\Lib\site-packages\telegram\request\_httpxrequest.py", line 293, in do_request
    res = await self._client.request(
          ^^^^^^^^^^^^^^^^^^^^^^^^^^^
  File "C:\Users\Admin\AppData\Local\Programs\Python\Python312\Lib\site-packages\httpx\_client.py", line 1585, in request
    return await self.send(request, auth=auth, follow_redirects=follow_redirects)
           ^^^^^^^^^^^^^^^^^^^^^^^^^^^^^^^^^^^^^^^^^^^^^^^^^^^^^^^^^^^^^^^^^^^^^^
  File "C:\Users\Admin\AppData\Local\Programs\Python\Python312\Lib\site-packages\httpx\_client.py", line 1674, in send
    response = await self._send_handling_auth(
               ^^^^^^^^^^^^^^^^^^^^^^^^^^^^^^^
  File "C:\Users\Admin\AppData\Local\Programs\Python\Python312\Lib\site-packages\httpx\_client.py", line 1702, in _send_handling_auth
    response = await self._send_handling_redirects(
               ^^^^^^^^^^^^^^^^^^^^^^^^^^^^^^^^^^^^
  File "C:\Users\Admin\AppData\Local\Programs\Python\Python312\Lib\site-packages\httpx\_client.py", line 1739, in _send_handling_redirects
    response = await self._send_single_request(request)
               ^^^^^^^^^^^^^^^^^^^^^^^^^^^^^^^^^^^^^^^^
  File "C:\Users\Admin\AppData\Local\Programs\Python\Python312\Lib\site-packages\httpx\_client.py", line 1776, in _send_single_request
    response = await transport.handle_async_request(request)
               ^^^^^^^^^^^^^^^^^^^^^^^^^^^^^^^^^^^^^^^^^^^^^
  File "C:\Users\Admin\AppData\Local\Programs\Python\Python312\Lib\site-packages\httpx\_transports\default.py", line 376, in handle_async_request
    with map_httpcore_exceptions():
  File "C:\Users\Admin\AppData\Local\Programs\Python\Python312\Lib\contextlib.py", line 158, in __exit__
    self.gen.throw(value)
  File "C:\Users\Admin\AppData\Local\Programs\Python\Python312\Lib\site-packages\httpx\_transports\default.py", line 89, in map_httpcore_exceptions
    raise mapped_exc(message) from exc
httpx.ConnectError: [Errno 11001] getaddrinfo failed

The above exception was the direct cause of the following exception:

Traceback (most recent call last):
  File "C:\Users\Admin\AppData\Local\Programs\Python\Python312\Lib\site-packages\telegram\ext\_updater.py", line 750, in _network_loop_retry
    if not await do_action():
           ^^^^^^^^^^^^^^^^^
  File "C:\Users\Admin\AppData\Local\Programs\Python\Python312\Lib\site-packages\telegram\ext\_updater.py", line 744, in do_action
    return action_cb_task.result()
           ^^^^^^^^^^^^^^^^^^^^^^^
  File "C:\Users\Admin\AppData\Local\Programs\Python\Python312\Lib\asyncio\futures.py", line 203, in result
    raise self._exception.with_traceback(self._exception_tb)
  File "C:\Users\Admin\AppData\Local\Programs\Python\Python312\Lib\asyncio\tasks.py", line 316, in __step_run_and_handle_result
    result = coro.throw(exc)
             ^^^^^^^^^^^^^^^
  File "C:\Users\Admin\AppData\Local\Programs\Python\Python312\Lib\site-packages\telegram\ext\_updater.py", line 371, in polling_action_cb
    updates = await self.bot.get_updates(
              ^^^^^^^^^^^^^^^^^^^^^^^^^^^
  File "C:\Users\Admin\AppData\Local\Programs\Python\Python312\Lib\site-packages\telegram\ext\_extbot.py", line 650, in get_updates
    updates = await super().get_updates(
              ^^^^^^^^^^^^^^^^^^^^^^^^^^
  File "C:\Users\Admin\AppData\Local\Programs\Python\Python312\Lib\site-packages\telegram\_bot.py", line 4480, in get_updates
    await self._post(
  File "C:\Users\Admin\AppData\Local\Programs\Python\Python312\Lib\site-packages\telegram\_bot.py", line 619, in _post
    return await self._do_post(
           ^^^^^^^^^^^^^^^^^^^^
  File "C:\Users\Admin\AppData\Local\Programs\Python\Python312\Lib\site-packages\telegram\ext\_extbot.py", line 354, in _do_post
    return await super()._do_post(
           ^^^^^^^^^^^^^^^^^^^^^^^
  File "C:\Users\Admin\AppData\Local\Programs\Python\Python312\Lib\site-packages\telegram\_bot.py", line 648, in _do_post
    result = await request.post(
             ^^^^^^^^^^^^^^^^^^^
  File "C:\Users\Admin\AppData\Local\Programs\Python\Python312\Lib\site-packages\telegram\request\_baserequest.py", line 202, in post
    result = await self._request_wrapper(
             ^^^^^^^^^^^^^^^^^^^^^^^^^^^^
  File "C:\Users\Admin\AppData\Local\Programs\Python\Python312\Lib\site-packages\telegram\request\_baserequest.py", line 334, in _request_wrapper
    code, payload = await self.do_request(
                    ^^^^^^^^^^^^^^^^^^^^^^
  File "C:\Users\Admin\AppData\Local\Programs\Python\Python312\Lib\site-packages\telegram\request\_httpxrequest.py", line 317, in do_request
    raise NetworkError(f"httpx.{err.__class__.__name__}: {err}") from err
telegram.error.NetworkError: httpx.ConnectError: [Errno 11001] getaddrinfo failed
2024-12-22 01:08:49,114 - __main__ - INFO - Команда /help вызвана.
2024-12-22 01:17:13,147 - __main__ - INFO - Команда /list вызвана.
2024-12-22 01:20:08,307 - __main__ - INFO - Пользователь 1753361154 просмотрел профиль пользователя 2128746010.
2024-12-22 01:20:21,771 - __main__ - INFO - Пользователь 1753361154 просмотрел профиль пользователя 1196314708.
2024-12-22 01:21:01,833 - __main__ - INFO - Пользователь 1753361154 отправил сообщение пользователю @Huapryanik (2128746010) анонимно=False.
2024-12-22 01:21:42,778 - __main__ - INFO - Пользователь 2128746010 ответил пользователю @shineSwa (1753361154) анонимно=False.
2024-12-22 01:21:54,826 - __main__ - INFO - Пользователь 2128746010 ответил пользователю @shineSwa (1753361154) анонимно=False.
2024-12-22 01:21:59,895 - __main__ - INFO - Пользователь 1753361154 ответил пользователю @Huapryanik (2128746010) анонимно=False.
2024-12-22 01:23:01,473 - __main__ - INFO - Пользователь 1753361154 изменил видимость профиля на 0.
2024-12-22 01:23:24,352 - __main__ - INFO - Пользователь 2128746010 ответил пользователю @shineSwa (1753361154) анонимно=False.
2024-12-22 01:24:58,786 - __main__ - INFO - Пользователь 1753361154 изменил видимость профиля на 1.
2024-12-22 01:25:49,876 - __main__ - INFO - Команда /list вызвана.
2024-12-22 01:26:02,335 - __main__ - INFO - Команда /info вызвана пользователем @shineSwa (1753361154).
2024-12-22 01:27:19,157 - __main__ - INFO - Пользователь 1753361154 просмотрел профиль пользователя 2128746010.
2024-12-22 01:27:54,054 - __main__ - INFO - Пользователь 1753361154 инициировал /start.
2024-12-22 01:28:13,001 - __main__ - INFO - Команда /rankings вызвана.
2024-12-22 01:28:19,779 - __main__ - INFO - Команда /myrank вызвана пользователем 1753361154.
2024-12-22 01:28:35,470 - __main__ - INFO - Команда /help вызвана.
2024-12-22 01:29:13,447 - __main__ - INFO - Пользователь 1753361154 искал пользователей по интересам: рисование
2024-12-22 01:30:12,469 - __main__ - INFO - Пользователь 1753361154 поставил лайк пользователю 1196314708 (@Syesonn).
2024-12-22 01:30:16,424 - __main__ - INFO - Пользователь 1753361154 инициировал /start.
2024-12-22 01:30:37,163 - __main__ - INFO - Пользователь 1753361154 просмотрел профиль пользователя 1196314708.
2024-12-22 01:30:56,915 - __main__ - INFO - Пользователь 1753361154 просмотрел профиль пользователя 2128746010.
2024-12-22 02:38:26,464 - __main__ - INFO - Пользователь 1753361154 просмотрел профиль пользователя 1196314708.
2024-12-22 02:38:47,995 - __main__ - INFO - Пользователь 1753361154 отправил сообщение пользователю @Syesonn (1196314708) анонимно=False.
2024-12-22 02:39:09,853 - __main__ - INFO - Пользователь 1753361154 отправил сообщение пользователю @Syesonn (1196314708) анонимно=False.
